Workbook

Sheet Orders Loaded
B2: ACTIVE ORDERS | I2: Janeth to update | L2: Pete to update | P2: Pete to update
B4: Row Labels | C4: Customer Name | D4: Type | E4: Loadout Date | F4: Sum of Total QTY | G4: Average of Price AUD | H4: Sum of Amount AUD | I4: Product Type | J4: CIF or FAS ? | K4: NRV (per kg) | L4: Livestock Cost per kg (HSCW) | M4: Pack Cost | N4: Offal Return PH | O4: Avg Skin Return | P4: Avg Weight | Q4: MoM PH | R4: Deposit Received | S4: Comments | T4: Do Not Buy Price | U4: Estimated number of heads required | V4: Total Livestock Cost
B5: CED18650 | C5: SHANGHAI NEW SOURCE | D5: SHEEP | E5: (blank) | F5: 25000 | G5: 10.144928 | H5: 250000 | I5: 6 WAY | J5: CIF | K5: =IF(J5="CIF",G5-0.3,G5) -> 9.8449275 | L5: 8.4 | M5: =_xlfn.IFNA(VLOOKUP(I5,Inputs!D:E,2,FALSE),0) -> 4 | N5: =_xlfn.IFNA(VLOOKUP(D5,Inputs!G:H,2,FALSE),0) -> 8 | O5: =_xlfn.IFNA(VLOOKUP(D5,Inputs!K:L,2,FALSE),0) -> 10 | P5: 22 | Q5: =IF(P5>0,(K5-L5)*P5+N5+O5-M5,0) -> 45.788406 | R5: =197005.8/2 -> 98502.9 | T5: =IF(P5>0,(K5)-((40+M5-O5-N5)/P5),0) -> 8.6631094 | U5: =IF(P5>0,(F5/P5),0) -> 1136.3636 | V5: =(L5*F5) -> 210000
B6: CED18651 | C6: SHANGHAI NEW SOURCE | D6: SHEEP | E6: (blank) | F6: 25000 | G6: 10.144928 | H6: 250000 | I6: 6 WAY | J6: CIF | K6: =IF(J6="CIF",G6-0.3,G6) -> 9.8449275 | L6: 8.4 | M6: =_xlfn.IFNA(VLOOKUP(I6,Inputs!D:E,2,FALSE),0) -> 4 | N6: =_xlfn.IFNA(VLOOKUP(D6,Inputs!G:H,2,FALSE),0) -> 8 | O6: =_xlfn.IFNA(VLOOKUP(D6,Inputs!K:L,2,FALSE),0) -> 10 | P6: 22 | Q6: =IF(P6>0,(K6-L6)*P6+N6+O6-M6,0) -> 45.788406 | R6: =197005.8/2 -> 98502.9 | T6: =IF(P6>0,(K6)-((40+M6-O6-N6)/P6),0) -> 8.6631094 | U6: =IF(P6>0,(F6/P6),0) -> 1136.3636 | V6: =(L6*F6) -> 210000
B7: CED18653 | C7: DALIAN MAGIC INTERNATIONAL | D7: SHEEP | E7: (blank) | F7: 22000 | G7: 9.7101449 | H7: 210571.43 | I7: 6 WAY | J7: CIF | K7: =IF(J7="CIF",G7-0.3,G7) -> 9.4101449 | L7: 8.4 | M7: =_xlfn.IFNA(VLOOKUP(I7,Inputs!D:E,2,FALSE),0) -> 4 | N7: =_xlfn.IFNA(VLOOKUP(D7,Inputs!G:H,2,FALSE),0) -> 8 | O7: =_xlfn.IFNA(VLOOKUP(D7,Inputs!K:L,2,FALSE),0) -> 10 | P7: 28 | Q7: =IF(P7>0,(K7-L7)*P7+N7+O7-M7,0) -> 42.284058 | T7: =IF(P7>0,(K7)-((40+M7-O7-N7)/P7),0) -> 8.4815735 | U7: =IF(P7>0,(F7/P7),0) -> 785.71429 | V7: =(L7*F7) -> 184800
B8: CED18655 | C8: DALIAN MAGIC INTERNATIONAL | D8: SHEEP | E8: (blank) | F8: 25000 | G8: 10.072464 | H8: 248214.29 | I8: 6 WAY | J8: CIF | K8: =IF(J8="CIF",G8-0.3,G8) -> 9.7724638 | L8: 8.4 | M8: =_xlfn.IFNA(VLOOKUP(I8,Inputs!D:E,2,FALSE),0) -> 4 | N8: =_xlfn.IFNA(VLOOKUP(D8,Inputs!G:H,2,FALSE),0) -> 8 | O8: =_xlfn.IFNA(VLOOKUP(D8,Inputs!K:L,2,FALSE),0) -> 10 | P8: 22 | Q8: =IF(P8>0,(K8-L8)*P8+N8+O8-M8,0) -> 44.194203 | T8: =IF(P8>0,(K8)-((40+M8-O8-N8)/P8),0) -> 8.5906456 | U8: =IF(P8>0,(F8/P8),0) -> 1136.3636 | V8: =(L8*F8) -> 210000
B9: CED18658 | C9: CHONGQING GOUZHAN INDUSTRIAL | D9: GOAT | E9: (blank) | F9: 24999 | G9: 10 | H9: 246418.71 | I9: 6 WAY | J9: CIF | K9: =IF(J9="CIF",G9-0.3,G9) -> 9.7 | L9: 7.7 | M9: =_xlfn.IFNA(VLOOKUP(I9,Inputs!D:E,2,FALSE),0) -> 4 | N9: =_xlfn.IFNA(VLOOKUP(D9,Inputs!G:H,2,FALSE),0) -> 6 | O9: 0.5 | P9: 14 | Q9: =IF(P9>0,(K9-L9)*P9+N9+O9-M9,0) -> 30.5 | R9: =240755.99/2 -> 120377.99 | T9: =IF(P9>0,(K9)-((40+M9-O9-N9)/P9),0) -> 7.0214286 | U9: =IF(P9>0,(F9/P9),0) -> 1785.6429 | V9: =(L9*F9) -> 192492.3
B10: CED18659 | C10: CHONGQING GOUZHAN INDUSTRIAL | D10: GOAT | E10: (blank) | F10: 24999 | G10: 10 | H10: 246418.71 | I10: 6 WAY | J10: CIF | K10: =IF(J10="CIF",G10-0.3,G10) -> 9.7 | L10: 7.7 | M10: =_xlfn.IFNA(VLOOKUP(I10,Inputs!D:E,2,FALSE),0) -> 4 | N10: =_xlfn.IFNA(VLOOKUP(D10,Inputs!G:H,2,FALSE),0) -> 6 | O10: 0.5 | P10: 14 | Q10: =IF(P10>0,(K10-L10)*P10+N10+O10-M10,0) -> 30.5 | R10: =240755.99/2 -> 120377.99 | T10: =IF(P10>0,(K10)-((40+M10-O10-N10)/P10),0) -> 7.0214286 | U10: =IF(P10>0,(F10/P10),0) -> 1785.6429 | V10: =(L10*F10) -> 192492.3
B11: CED18660 | C11: SHENZHEN YUESHI SUPPLY | D11: GOAT | E11: (blank) | F11: 24999 | G11: 10 | H11: 246418.71 | I11: 6 WAY | J11: CIF | K11: =IF(J11="CIF",G11-0.3,G11) -> 9.7 | L11: 7.7 | M11: =_xlfn.IFNA(VLOOKUP(I11,Inputs!D:E,2,FALSE),0) -> 4 | N11: =_xlfn.IFNA(VLOOKUP(D11,Inputs!G:H,2,FALSE),0) -> 6 | O11: 0.5 | P11: 14 | Q11: =IF(P11>0,(K11-L11)*P11+N11+O11-M11,0) -> 30.5 | R11: 72124.63 | T11: =IF(P11>0,(K11)-((40+M11-O11-N11)/P11),0) -> 7.0214286 | U11: =IF(P11>0,(F11/P11),0) -> 1785.6429 | V11: =(L11*F11) -> 192492.3
B12: CED18662 | C12: CHONGQING GOUZHAN INDUSTRIAL | D12: GOAT | E12: (blank) | F12: 17000 | G12: 10.289855 | H12: 172428.57 | I12: CCS | J12: CIF | K12: =IF(J12="CIF",G12-0.3,G12) -> 9.9898551 | L12: 7.7 | M12: =_xlfn.IFNA(VLOOKUP(I12,Inputs!D:E,2,FALSE),0) -> 2 | N12: =_xlfn.IFNA(VLOOKUP(D12,Inputs!G:H,2,FALSE),0) -> 6 | O12: 0.5 | P12: 10 | Q12: =IF(P12>0,(K12-L12)*P12+N12+O12-M12,0) -> 27.398551 | R12: 171364.63 | S12: 9 Ton Loaded | T12: =IF(P12>0,(K12)-((40+M12-O12-N12)/P12),0) -> 6.4398551 | U12: =IF(P12>0,(F12/P12),0) -> 1700 | V12: =(L12*F12) -> 130900
B13: CED18663 | C13: SHENZHEN YUESHI SUPPLY | D13: SHEEP | E13: (blank) | F13: 25000 | G13: 9.8550725 | H13: 242857.14 | I13: 6 WAY | J13: CIF | K13: =IF(J13="CIF",G13-0.3,G13) -> 9.5550725 | L13: 8.4 | M13: =_xlfn.IFNA(VLOOKUP(I13,Inputs!D:E,2,FALSE),0) -> 4 | N13: =_xlfn.IFNA(VLOOKUP(D13,Inputs!G:H,2,FALSE),0) -> 8 | O13: =_xlfn.IFNA(VLOOKUP(D13,Inputs!K:L,2,FALSE),0) -> 10 | P13: 27 | Q13: =IF(P13>0,(K13-L13)*P13+N13+O13-M13,0) -> 45.186957 | R13: =(93840/0.6963)/2 -> 67384.748 | T13: =IF(P13>0,(K13)-((40+M13-O13-N13)/P13),0) -> 8.5921095 | U13: =IF(P13>0,(F13/P13),0) -> 925.92593 | V13: =(L13*F13) -> 210000
B14: CED18664 | C14: SHENZHEN YUESHI SUPPLY | D14: SHEEP | E14: (blank) | F14: 25000 | G14: 9.8550725 | H14: 242857.14 | I14: 6 WAY | J14: CIF | K14: =IF(J14="CIF",G14-0.3,G14) -> 9.5550725 | L14: 8.4 | M14: =_xlfn.IFNA(VLOOKUP(I14,Inputs!D:E,2,FALSE),0) -> 4 | N14: =_xlfn.IFNA(VLOOKUP(D14,Inputs!G:H,2,FALSE),0) -> 8 | O14: =_xlfn.IFNA(VLOOKUP(D14,Inputs!K:L,2,FALSE),0) -> 10 | P14: 27 | Q14: =IF(P14>0,(K14-L14)*P14+N14+O14-M14,0) -> 45.186957 | R14: =(93840/0.6963)/2 -> 67384.748 | T14: =IF(P14>0,(K14)-((40+M14-O14-N14)/P14),0) -> 8.5921095 | U14: =IF(P14>0,(F14/P14),0) -> 925.92593 | V14: =(L14*F14) -> 210000
B15: CEDD7045 | C15: AGRICOMM | D15: VEAL | E15: (blank) | F15: 25000 | G15: 6.85 | H15: 171250 | I15: 6 WAY | J15: FAS | K15: =IF(J15="CIF",G15-0.3,G15) -> 6.85 | L15: 3.2 | M15: =_xlfn.IFNA(VLOOKUP(I15,Inputs!D:E,2,FALSE),0) -> 4 | N15: =_xlfn.IFNA(VLOOKUP(D15,Inputs!G:H,2,FALSE),0) -> 11 | O15: =_xlfn.IFNA(VLOOKUP(D15,Inputs!K:L,2,FALSE),0) -> 12 | P15: 17 | Q15: =IF(P15>0,(K15-L15)*P15+N15+O15-M15,0) -> 81.05 | R15: 166300.88 | T15: =IF(P15>0,(K15)-((40+M15-O15-N15)/P15),0) -> 5.6147059 | U15: =IF(P15>0,(F15/P15),0) -> 1470.5882 | V15: =(L15*F15) -> 80000
B16: CEDD7047 | C16: AGRICOMM | D16: VEAL | E16: (blank) | F16: 25000 | G16: 6.85 | H16: 171250 | I16: 6 WAY | J16: FAS | K16: =IF(J16="CIF",G16-0.3,G16) -> 6.85 | L16: 3.2 | M16: =_xlfn.IFNA(VLOOKUP(I16,Inputs!D:E,2,FALSE),0) -> 4 | N16: =_xlfn.IFNA(VLOOKUP(D16,Inputs!G:H,2,FALSE),0) -> 11 | O16: =_xlfn.IFNA(VLOOKUP(D16,Inputs!K:L,2,FALSE),0) -> 12 | P16: 17 | Q16: =IF(P16>0,(K16-L16)*P16+N16+O16-M16,0) -> 81.05 | T16: =IF(P16>0,(K16)-((40+M16-O16-N16)/P16),0) -> 5.6147059 | U16: =IF(P16>0,(F16/P16),0) -> 1470.5882 | V16: =(L16*F16) -> 80000
B17: CEDD7048 | C17: AGRICOMM | D17: VEAL | E17: (blank) | F17: 25000 | G17: 6.85 | H17: 171250 | I17: 6 WAY | J17: FAS | K17: =IF(J17="CIF",G17-0.3,G17) -> 6.85 | L17: 3.2 | M17: =_xlfn.IFNA(VLOOKUP(I17,Inputs!D:E,2,FALSE),0) -> 4 | N17: =_xlfn.IFNA(VLOOKUP(D17,Inputs!G:H,2,FALSE),0) -> 11 | O17: =_xlfn.IFNA(VLOOKUP(D17,Inputs!K:L,2,FALSE),0) -> 12 | P17: 17 | Q17: =IF(P17>0,(K17-L17)*P17+N17+O17-M17,0) -> 81.05 | T17: =IF(P17>0,(K17)-((40+M17-O17-N17)/P17),0) -> 5.6147059 | U17: =IF(P17>0,(F17/P17),0) -> 1470.5882 | V17: =(L17*F17) -> 80000
B18: CEDD7049 | C18: AGRICOMM | D18: VEAL | E18: (blank) | F18: 25000 | G18: 6.85 | H18: 171250 | I18: 6 WAY | J18: FAS | K18: =IF(J18="CIF",G18-0.3,G18) -> 6.85 | L18: 3.2 | M18: =_xlfn.IFNA(VLOOKUP(I18,Inputs!D:E,2,FALSE),0) -> 4 | N18: =_xlfn.IFNA(VLOOKUP(D18,Inputs!G:H,2,FALSE),0) -> 11 | O18: =_xlfn.IFNA(VLOOKUP(D18,Inputs!K:L,2,FALSE),0) -> 12 | P18: 17 | Q18: =IF(P18>0,(K18-L18)*P18+N18+O18-M18,0) -> 81.05 | T18: =IF(P18>0,(K18)-((40+M18-O18-N18)/P18),0) -> 5.6147059 | U18: =IF(P18>0,(F18/P18),0) -> 1470.5882 | V18: =(L18*F18) -> 80000
B19: CEDD7050 | C19: AGRICOMM | D19: VEAL | E19: (blank) | F19: 25000 | G19: 6.85 | H19: 171250 | I19: 6 WAY | J19: FAS | K19: =IF(J19="CIF",G19-0.3,G19) -> 6.85 | L19: 3.2 | M19: =_xlfn.IFNA(VLOOKUP(I19,Inputs!D:E,2,FALSE),0) -> 4 | N19: =_xlfn.IFNA(VLOOKUP(D19,Inputs!G:H,2,FALSE),0) -> 11 | O19: =_xlfn.IFNA(VLOOKUP(D19,Inputs!K:L,2,FALSE),0) -> 12 | P19: 17 | Q19: =IF(P19>0,(K19-L19)*P19+N19+O19-M19,0) -> 81.05 | T19: =IF(P19>0,(K19)-((40+M19-O19-N19)/P19),0) -> 5.6147059 | U19: =IF(P19>0,(F19/P19),0) -> 1470.5882 | V19: =(L19*F19) -> 80000
B20: CEDD7057 | C20: STELLA FOODS | D20: GOAT | E20: (blank) | F20: 24999 | G20: 9.5 | H20: 237490.5 | I20: 6 WAY | J20: FAS | K20: =IF(J20="CIF",G20-0.3,G20) -> 9.5 | L20: 7.7 | M20: =_xlfn.IFNA(VLOOKUP(I20,Inputs!D:E,2,FALSE),0) -> 4 | N20: =_xlfn.IFNA(VLOOKUP(D20,Inputs!G:H,2,FALSE),0) -> 6 | O20: 0.5 | P20: 14 | Q20: =IF(P20>0,(K20-L20)*P20+N20+O20-M20,0) -> 27.7 | T20: =IF(P20>0,(K20)-((40+M20-O20-N20)/P20),0) -> 6.8214286 | U20: =IF(P20>0,(F20/P20),0) -> 1785.6429 | V20: =(L20*F20) -> 192492.3
B21: CEDD7062 | C21: STELLA FOODS | D21: LAMB | E21: (blank) | F21: 17000 | G21: 11.6 | H21: 197200 | I21: CCS | J21: FAS | K21: =IF(J21="CIF",G21-0.3,G21) -> 11.6 | L21: 10.5 | M21: =_xlfn.IFNA(VLOOKUP(I21,Inputs!D:E,2,FALSE),0) -> 2 | N21: =_xlfn.IFNA(VLOOKUP(D21,Inputs!G:H,2,FALSE),0) -> 11 | O21: =_xlfn.IFNA(VLOOKUP(D21,Inputs!K:L,2,FALSE),0) -> 10 | P21: 18 | Q21: =IF(P21>0,(K21-L21)*P21+N21+O21-M21,0) -> 38.8 | T21: =IF(P21>0,(K21)-((40+M21-O21-N21)/P21),0) -> 10.433333 | U21: =IF(P21>0,(F21/P21),0) -> 944.44444 | V21: =(L21*F21) -> 178500
B22: CEDD7063 | C22: STELLA FOODS | D22: LAMB | E22: (blank) | F22: 17000 | G22: 11.6 | H22: 197200 | I22: CCS | J22: FAS | K22: =IF(J22="CIF",G22-0.3,G22) -> 11.6 | L22: 10.5 | M22: =_xlfn.IFNA(VLOOKUP(I22,Inputs!D:E,2,FALSE),0) -> 2 | N22: =_xlfn.IFNA(VLOOKUP(D22,Inputs!G:H,2,FALSE),0) -> 11 | O22: =_xlfn.IFNA(VLOOKUP(D22,Inputs!K:L,2,FALSE),0) -> 10 | P22: 18 | Q22: =IF(P22>0,(K22-L22)*P22+N22+O22-M22,0) -> 38.8 | T22: =IF(P22>0,(K22)-((40+M22-O22-N22)/P22),0) -> 10.433333 | U22: =IF(P22>0,(F22/P22),0) -> 944.44444 | V22: =(L22*F22) -> 178500
B23: CEDD7065 | C23: AGRICOMM | D23: GOAT | E23: (blank) | F23: 25000 | G23: 9.8 | H23: 245000 | I23: 6 WAY | J23: FAS | K23: =IF(J23="CIF",G23-0.3,G23) -> 9.8 | L23: 7.7 | M23: =_xlfn.IFNA(VLOOKUP(I23,Inputs!D:E,2,FALSE),0) -> 4 | N23: =_xlfn.IFNA(VLOOKUP(D23,Inputs!G:H,2,FALSE),0) -> 6 | O23: 0.5 | P23: 14 | Q23: =IF(P23>0,(K23-L23)*P23+N23+O23-M23,0) -> 31.9 | T23: =IF(P23>0,(K23)-((40+M23-O23-N23)/P23),0) -> 7.1214286 | U23: =IF(P23>0,(F23/P23),0) -> 1785.7143 | V23: =(L23*F23) -> 192500
B24: CEDD7069 | C24: GLOBAL MEAT COMMODITIES | D24: GOAT | E24: (blank) | F24: 24000 | G24: 9.65 | H24: 231600 | I24: 6 WAY | J24: FAS | K24: =IF(J24="CIF",G24-0.3,G24) -> 9.65 | L24: 7.7 | M24: =_xlfn.IFNA(VLOOKUP(I24,Inputs!D:E,2,FALSE),0) -> 4 | N24: =_xlfn.IFNA(VLOOKUP(D24,Inputs!G:H,2,FALSE),0) -> 6 | O24: 0.5 | P24: 14 | Q24: =IF(P24>0,(K24-L24)*P24+N24+O24-M24,0) -> 29.8 | T24: =IF(P24>0,(K24)-((40+M24-O24-N24)/P24),0) -> 6.9714286 | U24: =IF(P24>0,(F24/P24),0) -> 1714.2857 | V24: =(L24*F24) -> 184800
B25: CED18669 | C25: CHONGQING GOUZHAN INDUSTRIAL | D25: GOAT | E25: (blank) | F25: 16000 | G25: 10.072464 | H25: 158857.14 | I25: CCS | J25: CIF | K25: =IF(J25="CIF",G25-0.3,G25) -> 9.7724638 | L25: 7.7 | M25: =_xlfn.IFNA(VLOOKUP(I25,Inputs!D:E,2,FALSE),0) -> 2 | N25: =_xlfn.IFNA(VLOOKUP(D25,Inputs!G:H,2,FALSE),0) -> 6 | O25: 0.5 | P25: 10 | Q25: =IF(P25>0,(K25-L25)*P25+N25+O25-M25,0) -> 25.224638 | T25: =IF(P25>0,(K25)-((40+M25-O25-N25)/P25),0) -> 6.2224638 | U25: =IF(P25>0,(F25/P25),0) -> 1600 | V25: =(L25*F25) -> 123200
B26: CED18670 | C26: CHONGQING GOUZHAN INDUSTRIAL | D26: GOAT | E26: (blank) | F26: 16000 | G26: 10.144928 | H26: 160000 | I26: CCS | J26: CIF | K26: =IF(J26="CIF",G26-0.3,G26) -> 9.8449275 | L26: 7.7 | M26: =_xlfn.IFNA(VLOOKUP(I26,Inputs!D:E,2,FALSE),0) -> 2 | N26: =_xlfn.IFNA(VLOOKUP(D26,Inputs!G:H,2,FALSE),0) -> 6 | O26: 0.5 | P26: 10 | Q26: =IF(P26>0,(K26-L26)*P26+N26+O26-M26,0) -> 25.949275 | T26: =IF(P26>0,(K26)-((40+M26-O26-N26)/P26),0) -> 6.2949275 | U26: =IF(P26>0,(F26/P26),0) -> 1600 | V26: =(L26*F26) -> 123200
B27: CEDD7076 | C27: GLOBAL MEAT COMMODITIES | D27: GOAT | E27: (blank) | F27: 24000 | G27: 9.75 | H27: 234000 | I27: 6 WAY | J27: FAS | K27: =IF(J27="CIF",G27-0.3,G27) -> 9.75 | L27: 7.7 | M27: =_xlfn.IFNA(VLOOKUP(I27,Inputs!D:E,2,FALSE),0) -> 4 | N27: =_xlfn.IFNA(VLOOKUP(D27,Inputs!G:H,2,FALSE),0) -> 6 | O27: 0.5 | P27: 14 | Q27: =IF(P27>0,(K27-L27)*P27+N27+O27-M27,0) -> 31.2 | T27: =IF(P27>0,(K27)-((40+M27-O27-N27)/P27),0) -> 7.0714286 | U27: =IF(P27>0,(F27/P27),0) -> 1714.2857 | V27: =(L27*F27) -> 184800
B28: CEDD7085 | C28: BOUNTY FOODS | D28: LAMB | E28: (blank) | F28: 8100 | G28: 10.375 | H28: 83800 | I28: FULL BONE | J28: FAS | K28: =IF(J28="CIF",G28-0.3,G28) -> 10.375 | L28: 10.5 | M28: =_xlfn.IFNA(VLOOKUP(I28,Inputs!D:E,2,FALSE),0) -> 7 | N28: =_xlfn.IFNA(VLOOKUP(D28,Inputs!G:H,2,FALSE),0) -> 11 | O28: =_xlfn.IFNA(VLOOKUP(D28,Inputs!K:L,2,FALSE),0) -> 10 | P28: 18 | Q28: =IF(P28>0,(K28-L28)*P28+N28+O28-M28,0) -> 11.75 | T28: =IF(P28>0,(K28)-((40+M28-O28-N28)/P28),0) -> 8.9305556 | U28: =IF(P28>0,(F28/P28),0) -> 450 | V28: =(L28*F28) -> 85050
B29: CEDD7089 | C29: GLOBAL MEAT COMMODITIES | D29: GOAT | E29: (blank) | F29: 25000 | G29: 10 | H29: 250000 | I29: 6 WAY | J29: FAS | K29: =IF(J29="CIF",G29-0.3,G29) -> 10 | L29: 7.7 | M29: =_xlfn.IFNA(VLOOKUP(I29,Inputs!D:E,2,FALSE),0) -> 4 | N29: =_xlfn.IFNA(VLOOKUP(D29,Inputs!G:H,2,FALSE),0) -> 6 | O29: 0.5 | P29: 14 | Q29: =IF(P29>0,(K29-L29)*P29+N29+O29-M29,0) -> 34.7 | T29: =IF(P29>0,(K29)-((40+M29-O29-N29)/P29),0) -> 7.3214286 | U29: =IF(P29>0,(F29/P29),0) -> 1785.7143 | V29: =(L29*F29) -> 192500
B30: CEDD7092 | C30: AGRICOMM | D30: VEAL | E30: (blank) | F30: 25000 | G30: 7.05 | H30: 176250 | I30: 6 WAY | J30: FAS | K30: =IF(J30="CIF",G30-0.3,G30) -> 7.05 | L30: 3.2 | M30: =_xlfn.IFNA(VLOOKUP(I30,Inputs!D:E,2,FALSE),0) -> 4 | N30: =_xlfn.IFNA(VLOOKUP(D30,Inputs!G:H,2,FALSE),0) -> 11 | O30: =_xlfn.IFNA(VLOOKUP(D30,Inputs!K:L,2,FALSE),0) -> 12 | P30: 17 | Q30: =IF(P30>0,(K30-L30)*P30+N30+O30-M30,0) -> 84.45 | T30: =IF(P30>0,(K30)-((40+M30-O30-N30)/P30),0) -> 5.8147059 | U30: =IF(P30>0,(F30/P30),0) -> 1470.5882 | V30: =(L30*F30) -> 80000
B31: CEDD7093 | C31: AGRICOMM | D31: VEAL | E31: (blank) | F31: 25000 | G31: 7.05 | H31: 176250 | I31: 6 WAY | J31: FAS | K31: =IF(J31="CIF",G31-0.3,G31) -> 7.05 | L31: 3.2 | M31: =_xlfn.IFNA(VLOOKUP(I31,Inputs!D:E,2,FALSE),0) -> 4 | N31: =_xlfn.IFNA(VLOOKUP(D31,Inputs!G:H,2,FALSE),0) -> 11 | O31: =_xlfn.IFNA(VLOOKUP(D31,Inputs!K:L,2,FALSE),0) -> 12 | P31: 17 | Q31: =IF(P31>0,(K31-L31)*P31+N31+O31-M31,0) -> 84.45 | T31: =IF(P31>0,(K31)-((40+M31-O31-N31)/P31),0) -> 5.8147059 | U31: =IF(P31>0,(F31/P31),0) -> 1470.5882 | V31: =(L31*F31) -> 80000
B32: Grand Total | F32: =SUM(F5:F31) -> 611096 | G32: =(H32/F32) -> 9.0985416 | H32: =SUM(H5:H31) -> 5560082.4 | R32: =SUM(R5:R31) -> 982321.43
B35: LOADED ORDERS
B36: Row Labels | C36: Customer Name | D36: Type | E36: Loadout Date | F36: Sum of Total QTY | G36: Average of Price AUD | H36: Sum of Amount AUD | I36: Product Type | J36: CIF or FAS ? | K36: NRV (per kg) | L36: Livestock Cost per kg (HSCW) | M36: Pack Cost | N36: Offal Return PH | O36: Avg Skin Return | P36: Avg Weight | Q36: MoM PH | S36: Comments | T36: Do Not Buy Price | U36: Estimated number of heads required | V36: Total Livestock Cost
B37: CED18649 | C37: TIANJIN NAVIGATOR INTERNATIONAL | D37: SHEEP | E37: 46205 | F37: 21617.16 | G37: 9.7101449 | H37: 206907.1 | I37: 6 WAY | J37: CIF | K37: =IF(J37="CIF",G37-0.3,G37) -> 9.4101449 | L37: 8.81 | M37: =_xlfn.IFNA(VLOOKUP(I37,Inputs!D:E,2,FALSE),0) -> 4 | N37: =_xlfn.IFNA(VLOOKUP(D37,Inputs!G:H,2,FALSE),0) -> 8 | O37: =_xlfn.IFNA(VLOOKUP(D37,Inputs!K:L,2,FALSE),0) -> 10 | P37: 24.89 | Q37: =IF(P37>0,(K37-L37)*P37+N37+O37-M37,0) -> 28.937607 | T37: =IF(P37>0,(K37)-((34+M37-O37-N37)/P37),0) -> 8.6066094 | U37: =IF(P37>0,(F37/P37),0) -> 868.50783 | V37: =(L37*F37) -> 190447.18
B38: CED18654 | C38: DALIAN MAGIC INTERNATIONAL | D38: SHEEP | E38: 46212 | F38: 25004.6 | G38: 10.072464 | H38: 248259.96 | I38: 6 WAY | J38: CIF | K38: =IF(J38="CIF",G38-0.3,G38) -> 9.7724638 | L38: 8.21 | M38: =_xlfn.IFNA(VLOOKUP(I38,Inputs!D:E,2,FALSE),0) -> 4 | N38: =_xlfn.IFNA(VLOOKUP(D38,Inputs!G:H,2,FALSE),0) -> 8 | O38: =_xlfn.IFNA(VLOOKUP(D38,Inputs!K:L,2,FALSE),0) -> 10 | P38: 18.24 | Q38: =IF(P38>0,(K38-L38)*P38+N38+O38-M38,0) -> 42.499339 | T38: =IF(P38>0,(K38)-((34+M38-O38-N38)/P38),0) -> 8.6759725 | U38: =IF(P38>0,(F38/P38),0) -> 1370.8662 | V38: =(L38*F38) -> 205287.77
B39: CED18656 | C39: JINAN WELCOME INDUSTRIAL | D39: MUTTON | E39: 46202 | F39: 15503.2 | G39: 9.7101449 | H39: 148387.77 | I39: CCS | J39: CIF | K39: =IF(J39="CIF",G39-0.3,G39) -> 9.4101449 | L39: 7.8 | M39: =_xlfn.IFNA(VLOOKUP(I39,Inputs!D:E,2,FALSE),0) -> 2 | N39: =_xlfn.IFNA(VLOOKUP(D39,Inputs!G:H,2,FALSE),0) -> 8 | O39: =_xlfn.IFNA(VLOOKUP(D39,Inputs!K:L,2,FALSE),0) -> 10 | P39: 23.3 | Q39: =IF(P39>0,(K39-L39)*P39+N39+O39-M39,0) -> 53.516377 | T39: =IF(P39>0,(K39)-((34+M39-O39-N39)/P39),0) -> 8.6376127 | U39: =IF(P39>0,(F39/P39),0) -> 665.37339 | V39: =(L39*F39) -> 120924.96
B40: CEDD7044 | C40: AGRICOMM | D40: VEAL | E40: 46210 | F40: 25008.88 | G40: 6.85 | H40: 171310.83 | I40: 6 WAY | J40: FAS | K40: =IF(J40="CIF",G40-0.3,G40) -> 6.85 | L40: 3.11 | M40: =_xlfn.IFNA(VLOOKUP(I40,Inputs!D:E,2,FALSE),0) -> 4 | N40: =_xlfn.IFNA(VLOOKUP(D40,Inputs!G:H,2,FALSE),0) -> 11 | O40: =_xlfn.IFNA(VLOOKUP(D40,Inputs!K:L,2,FALSE),0) -> 12 | P40: 18.8 | Q40: =IF(P40>0,(K40-L40)*P40+N40+O40-M40,0) -> 89.312 | T40: =IF(P40>0,(K40)-((34+M40-O40-N40)/P40),0) -> 6.0521277 | U40: =IF(P40>0,(F40/P40),0) -> 1330.2596 | V40: =(L40*F40) -> 77777.617
B41: CEDD7060 | C41: AGRICOMM | D41: LAMB | E41: 46206 | F41: 15221.1 | G41: 11.5 | H41: 175042.65 | I41: CCS | J41: FAS | K41: =IF(J41="CIF",G41-0.3,G41) -> 11.5 | L41: 10.35 | M41: =_xlfn.IFNA(VLOOKUP(I41,Inputs!D:E,2,FALSE),0) -> 2 | N41: =_xlfn.IFNA(VLOOKUP(D41,Inputs!G:H,2,FALSE),0) -> 11 | O41: =_xlfn.IFNA(VLOOKUP(D41,Inputs!K:L,2,FALSE),0) -> 10 | P41: 18.06 | Q41: =IF(P41>0,(K41-L41)*P41+N41+O41-M41,0) -> 39.769 | T41: =IF(P41>0,(K41)-((34+M41-O41-N41)/P41),0) -> 10.669435 | U41: =IF(P41>0,(F41/P41),0) -> 842.80731 | V41: =(L41*F41) -> 157538.39
B42: CEDD7067 | C42: MIDFIELD COMMODITIES | D42: VEAL | E42: 46219 | F42: 25000.18 | G42: 6.65 | H42: 166251.2 | I42: 6 WAY | J42: FAS | K42: =IF(J42="CIF",G42-0.3,G42) -> 6.65 | L42: 3.13 | M42: =_xlfn.IFNA(VLOOKUP(I42,Inputs!D:E,2,FALSE),0) -> 4 | N42: =_xlfn.IFNA(VLOOKUP(D42,Inputs!G:H,2,FALSE),0) -> 11 | O42: =_xlfn.IFNA(VLOOKUP(D42,Inputs!K:L,2,FALSE),0) -> 12 | P42: 18.2 | Q42: =IF(P42>0,(K42-L42)*P42+N42+O42-M42,0) -> 83.064 | T42: =IF(P42>0,(K42)-((34+M42-O42-N42)/P42),0) -> 5.8258242 | U42: =IF(P42>0,(F42/P42),0) -> 1373.6363 | V42: =(L42*F42) -> 78250.563
B43: CEDD7070 | C43: SWIFT & COMPANY | D43: LAMB | E43: 46206 | F43: 9836.3 | G43: 11 | H43: 108199.3 | I43: 6 WAY | J43: FAS | K43: =IF(J43="CIF",G43-0.3,G43) -> 11 | L43: 10.18 | M43: =_xlfn.IFNA(VLOOKUP(I43,Inputs!D:E,2,FALSE),0) -> 4 | N43: =_xlfn.IFNA(VLOOKUP(D43,Inputs!G:H,2,FALSE),0) -> 11 | O43: =_xlfn.IFNA(VLOOKUP(D43,Inputs!K:L,2,FALSE),0) -> 10 | P43: 18.34 | Q43: =IF(P43>0,(K43-L43)*P43+N43+O43-M43,0) -> 32.0388 | T43: =IF(P43>0,(K43)-((34+M43-O43-N43)/P43),0) -> 10.073064 | U43: =IF(P43>0,(F43/P43),0) -> 536.33043 | V43: =(L43*F43) -> 100133.53
B44: CEDD7072 | C44: GLOBAL MEAT COMMODITIES | D44: GOAT | E44: 46212 | F44: 24026.78 | G44: 9.75 | H44: 234261.11 | I44: 6 WAY | J44: FAS | K44: =IF(J44="CIF",G44-0.3,G44) -> 9.75 | L44: 8.27 | M44: =_xlfn.IFNA(VLOOKUP(I44,Inputs!D:E,2,FALSE),0) -> 4 | N44: =_xlfn.IFNA(VLOOKUP(D44,Inputs!G:H,2,FALSE),0) -> 6 | O44: =_xlfn.IFNA(VLOOKUP(D44,Inputs!K:L,2,FALSE),0) -> 0 | P44: 16.63 | Q44: =IF(P44>0,(K44-L44)*P44+N44+O44-M44,0) -> 26.6124 | T44: =IF(P44>0,(K44)-((34+M44-O44-N44)/P44),0) -> 7.8257667 | U44: =IF(P44>0,(F44/P44),0) -> 1444.7853 | V44: =(L44*F44) -> 198701.47
...

Sheet Profitability Analysis
B2: ACTIVE ORDERS TO BE COMPLETED BY JANETH | L2: Data Input_Peter | P2: Data Input_Peter
B4: Contract No. | C4: Customer Name | D4: Type | E4: Loadout Date | F4: Sum of Total QTY | G4: Average of Price AUD | H4: Sum of Amount AUD | I4: Product Type | J4: CIF or FAS ? | K4: NRV (per kg) | L4: EXPECTED Livestock Cost per kg (HSCW) | M4: Pack Cost | N4: Offal Return PH | O4: Avg Skin Return | P4: Avg Weight | Q4: MoM PH | R4: Deposit Received | S4: Do Not Buy Price_Using % method instructed by the financier | T4: Estimated number of heads required | U4: Total Livestock Cost
B5: CED18650 | C5: SHANGHAI NEW SOURCE | D5: SHEEP | E5: (blank) | F5: 25000 | G5: 10.144928 | H5: 250000 | I5: 6 WAY | J5: CIF | K5: =IF(J5="CIF",G5-0.3,G5) -> 9.8449275 | L5: 8.4 | M5: =_xlfn.IFNA(VLOOKUP(I5,Inputs!D:E,2,FALSE),0) -> 4 | N5: =_xlfn.IFNA(VLOOKUP(D5,Inputs!G:H,2,FALSE),0) -> 8 | O5: =_xlfn.IFNA(VLOOKUP(D5,Inputs!K:L,2,FALSE),0) -> 10 | P5: 22 | Q5: =(K5-L5)*P5+N5+O5-M5 -> 45.788406 | R5: 98502.9 | S5: =K5/(VLOOKUP(D5,Inputs!R:S,2,FALSE)+1) -> 8.2041063 | T5: =IF(P5>0,(F5/P5),0) -> 1136.3636 | U5: =(L5*F5) -> 210000
B6: CED18651 | C6: SHANGHAI NEW SOURCE | D6: SHEEP | E6: (blank) | F6: 25000 | G6: 10.144928 | H6: 250000 | I6: 6 WAY | J6: CIF | K6: =IF(J6="CIF",G6-0.3,G6) -> 9.8449275 | L6: 8.4 | M6: =_xlfn.IFNA(VLOOKUP(I6,Inputs!D:E,2,FALSE),0) -> 4 | N6: =_xlfn.IFNA(VLOOKUP(D6,Inputs!G:H,2,FALSE),0) -> 8 | O6: =_xlfn.IFNA(VLOOKUP(D6,Inputs!K:L,2,FALSE),0) -> 10 | P6: 22 | Q6: =(K6-L6)*P6+N6+O6-M6 -> 45.788406 | R6: 98502.9 | S6: =K6/(VLOOKUP(D6,Inputs!R:S,2,FALSE)+1) -> 8.2041063 | T6: =IF(P6>0,(F6/P6),0) -> 1136.3636 | U6: =(L6*F6) -> 210000
B7: CED18653 | C7: DALIAN MAGIC INTERNATIONAL | D7: SHEEP | E7: (blank) | F7: 22000 | G7: 9.7101449 | H7: 210571.43 | I7: 6 WAY | J7: CIF | K7: =IF(J7="CIF",G7-0.3,G7) -> 9.4101449 | L7: 8.4 | M7: =_xlfn.IFNA(VLOOKUP(I7,Inputs!D:E,2,FALSE),0) -> 4 | N7: =_xlfn.IFNA(VLOOKUP(D7,Inputs!G:H,2,FALSE),0) -> 8 | O7: =_xlfn.IFNA(VLOOKUP(D7,Inputs!K:L,2,FALSE),0) -> 10 | P7: 28 | Q7: =(K7-L7)*P7+N7+O7-M7 -> 42.284058 | R7: 0 | S7: =K7/(VLOOKUP(D7,Inputs!R:S,2,FALSE)+1) -> 7.8417874 | T7: =IF(P7>0,(F7/P7),0) -> 785.71429 | U7: =(L7*F7) -> 184800
B8: CED18655 | C8: DALIAN MAGIC INTERNATIONAL | D8: SHEEP | E8: (blank) | F8: 25000 | G8: 10.072464 | H8: 248214.29 | I8: 6 WAY | J8: CIF | K8: =IF(J8="CIF",G8-0.3,G8) -> 9.7724638 | L8: 8.4 | M8: =_xlfn.IFNA(VLOOKUP(I8,Inputs!D:E,2,FALSE),0) -> 4 | N8: =_xlfn.IFNA(VLOOKUP(D8,Inputs!G:H,2,FALSE),0) -> 8 | O8: =_xlfn.IFNA(VLOOKUP(D8,Inputs!K:L,2,FALSE),0) -> 10 | P8: 22 | Q8: =(K8-L8)*P8+N8+O8-M8 -> 44.194203 | R8: 0 | S8: =K8/(VLOOKUP(D8,Inputs!R:S,2,FALSE)+1) -> 8.1437198 | T8: =IF(P8>0,(F8/P8),0) -> 1136.3636 | U8: =(L8*F8) -> 210000
B9: CED18658 | C9: CHONGQING GOUZHAN INDUSTRIAL | D9: GOAT | E9: (blank) | F9: 24999 | G9: 10 | H9: 246418.71 | I9: 6 WAY | J9: CIF | K9: =IF(J9="CIF",G9-0.3,G9) -> 9.7 | L9: 7.7 | M9: =_xlfn.IFNA(VLOOKUP(I9,Inputs!D:E,2,FALSE),0) -> 4 | N9: =_xlfn.IFNA(VLOOKUP(D9,Inputs!G:H,2,FALSE),0) -> 6 | O9: =_xlfn.IFNA(VLOOKUP(D9,Inputs!K:L,2,FALSE),0) -> 0 | P9: 14 | Q9: =(K9-L9)*P9+N9+O9-M9 -> 30 | R9: 120377.99 | S9: =K9/(VLOOKUP(D9,Inputs!R:S,2,FALSE)+1) -> 7.4615385 | T9: =IF(P9>0,(F9/P9),0) -> 1785.6429 | U9: =(L9*F9) -> 192492.3
B10: CED18659 | C10: CHONGQING GOUZHAN INDUSTRIAL | D10: GOAT | E10: (blank) | F10: 24999 | G10: 10 | H10: 246418.71 | I10: 6 WAY | J10: CIF | K10: =IF(J10="CIF",G10-0.3,G10) -> 9.7 | L10: 7.7 | M10: =_xlfn.IFNA(VLOOKUP(I10,Inputs!D:E,2,FALSE),0) -> 4 | N10: =_xlfn.IFNA(VLOOKUP(D10,Inputs!G:H,2,FALSE),0) -> 6 | O10: =_xlfn.IFNA(VLOOKUP(D10,Inputs!K:L,2,FALSE),0) -> 0 | P10: 14 | Q10: =(K10-L10)*P10+N10+O10-M10 -> 30 | R10: 120377.99 | S10: =K10/(VLOOKUP(D10,Inputs!R:S,2,FALSE)+1) -> 7.4615385 | T10: =IF(P10>0,(F10/P10),0) -> 1785.6429 | U10: =(L10*F10) -> 192492.3
B11: CED18660 | C11: SHENZHEN YUESHI SUPPLY | D11: GOAT | E11: (blank) | F11: 24999 | G11: 10 | H11: 246418.71 | I11: 6 WAY | J11: CIF | K11: =IF(J11="CIF",G11-0.3,G11) -> 9.7 | L11: 7.7 | M11: =_xlfn.IFNA(VLOOKUP(I11,Inputs!D:E,2,FALSE),0) -> 4 | N11: =_xlfn.IFNA(VLOOKUP(D11,Inputs!G:H,2,FALSE),0) -> 6 | O11: =_xlfn.IFNA(VLOOKUP(D11,Inputs!K:L,2,FALSE),0) -> 0 | P11: 14 | Q11: =(K11-L11)*P11+N11+O11-M11 -> 30 | R11: 72124.63 | S11: =K11/(VLOOKUP(D11,Inputs!R:S,2,FALSE)+1) -> 7.4615385 | T11: =IF(P11>0,(F11/P11),0) -> 1785.6429 | U11: =(L11*F11) -> 192492.3
B12: CED18662 | C12: CHONGQING GOUZHAN INDUSTRIAL | D12: GOAT | E12: (blank) | F12: 17000 | G12: 10.289855 | H12: 172428.57 | I12: CCS | J12: CIF | K12: =IF(J12="CIF",G12-0.3,G12) -> 9.9898551 | L12: 7.7 | M12: =_xlfn.IFNA(VLOOKUP(I12,Inputs!D:E,2,FALSE),0) -> 2 | N12: =_xlfn.IFNA(VLOOKUP(D12,Inputs!G:H,2,FALSE),0) -> 6 | O12: =_xlfn.IFNA(VLOOKUP(D12,Inputs!K:L,2,FALSE),0) -> 0 | P12: 10 | Q12: =(K12-L12)*P12+N12+O12-M12 -> 26.898551 | R12: 171364.63 | S12: =K12/(VLOOKUP(D12,Inputs!R:S,2,FALSE)+1) -> 7.6845039 | T12: =IF(P12>0,(F12/P12),0) -> 1700 | U12: =(L12*F12) -> 130900
B13: CED18663 | C13: SHENZHEN YUESHI SUPPLY | D13: SHEEP | E13: (blank) | F13: 25000 | G13: 9.8550725 | H13: 242857.14 | I13: 6 WAY | J13: CIF | K13: =IF(J13="CIF",G13-0.3,G13) -> 9.5550725 | L13: 8.4 | M13: =_xlfn.IFNA(VLOOKUP(I13,Inputs!D:E,2,FALSE),0) -> 4 | N13: =_xlfn.IFNA(VLOOKUP(D13,Inputs!G:H,2,FALSE),0) -> 8 | O13: =_xlfn.IFNA(VLOOKUP(D13,Inputs!K:L,2,FALSE),0) -> 10 | P13: 27 | Q13: =(K13-L13)*P13+N13+O13-M13 -> 45.186957 | R13: 67384.748 | S13: =K13/(VLOOKUP(D13,Inputs!R:S,2,FALSE)+1) -> 7.9625604 | T13: =IF(P13>0,(F13/P13),0) -> 925.92593 | U13: =(L13*F13) -> 210000
B14: CED18664 | C14: SHENZHEN YUESHI SUPPLY | D14: SHEEP | E14: (blank) | F14: 25000 | G14: 9.8550725 | H14: 242857.14 | I14: 6 WAY | J14: CIF | K14: =IF(J14="CIF",G14-0.3,G14) -> 9.5550725 | L14: 8.4 | M14: =_xlfn.IFNA(VLOOKUP(I14,Inputs!D:E,2,FALSE),0) -> 4 | N14: =_xlfn.IFNA(VLOOKUP(D14,Inputs!G:H,2,FALSE),0) -> 8 | O14: =_xlfn.IFNA(VLOOKUP(D14,Inputs!K:L,2,FALSE),0) -> 10 | P14: 27 | Q14: =(K14-L14)*P14+N14+O14-M14 -> 45.186957 | R14: 67384.748 | S14: =K14/(VLOOKUP(D14,Inputs!R:S,2,FALSE)+1) -> 7.9625604 | T14: =IF(P14>0,(F14/P14),0) -> 925.92593 | U14: =(L14*F14) -> 210000
B15: CEDD7045 | C15: AGRICOMM | D15: VEAL | E15: (blank) | F15: 25000 | G15: 6.85 | H15: 171250 | I15: 6 WAY | J15: FAS | K15: =IF(J15="CIF",G15-0.3,G15) -> 6.85 | L15: 3.2 | M15: =_xlfn.IFNA(VLOOKUP(I15,Inputs!D:E,2,FALSE),0) -> 4 | N15: =_xlfn.IFNA(VLOOKUP(D15,Inputs!G:H,2,FALSE),0) -> 11 | O15: =_xlfn.IFNA(VLOOKUP(D15,Inputs!K:L,2,FALSE),0) -> 12 | P15: 17 | Q15: =(K15-L15)*P15+N15+O15-M15 -> 81.05 | R15: 166300.88 | S15: =K15/(VLOOKUP(D15,Inputs!R:S,2,FALSE)+1) -> 4.8928571 | T15: =IF(P15>0,(F15/P15),0) -> 1470.5882 | U15: =(L15*F15) -> 80000
B16: CEDD7048 | C16: AGRICOMM | D16: VEAL | E16: (blank) | F16: 25000 | G16: 6.85 | H16: 171250 | I16: 6 WAY | J16: FAS | K16: =IF(J16="CIF",G16-0.3,G16) -> 6.85 | L16: 3.25 | M16: =_xlfn.IFNA(VLOOKUP(I16,Inputs!D:E,2,FALSE),0) -> 4 | N16: =_xlfn.IFNA(VLOOKUP(D16,Inputs!G:H,2,FALSE),0) -> 11 | O16: =_xlfn.IFNA(VLOOKUP(D16,Inputs!K:L,2,FALSE),0) -> 12 | P16: 17 | Q16: =(K16-L16)*P16+N16+O16-M16 -> 80.2 | R16: 0 | S16: =K16/(VLOOKUP(D16,Inputs!R:S,2,FALSE)+1) -> 4.8928571 | T16: =IF(P16>0,(F16/P16),0) -> 1470.5882 | U16: =(L16*F16) -> 81250
... B30: CEDD7093 | C30: AGRICOMM | D30: VEAL | E30: (blank) | F30: 25000 | G30: 7.05 | H30: 176250 | I30: 6 WAY | J30: FAS | K30: =IF(J30="CIF",G30-0.3,G30) -> 7.05 | L30: 3.25 | M30: =_xlfn.IFNA(VLOOKUP(I30,Inputs!D:E,2,FALSE),0) -> 4 | N30: =_xlfn.IFNA(VLOOKUP(D30,Inputs!G:H,2,FALSE),0) -> 11 | O30: =_xlfn.IFNA(VLOOKUP(D30,Inputs!K:L,2,FALSE),0) -> 12 | P30: 17 | Q30: =(K30-L30)*P30+N30+O30-M30 -> 83.6 | R30: 0 | S30: =K30/(VLOOKUP(D30,Inputs!R:S,2,FALSE)+1) -> 5.0357143 | T30: =IF(P30>0,(F30/P30),0) -> 1470.5882 | U30: =(L30*F30) -> 81250
B31: CEDD7094 | C31: STELLA FOODS | D31: VEAL | E31: (blank) | F31: 25000.18 | G31: 6.8 | H31: 170001.22 | I31: 6 WAY | J31: FAS | K31: =IF(J31="CIF",G31-0.3,G31) -> 6.8 | L31: 3.25 | M31: =_xlfn.IFNA(VLOOKUP(I31,Inputs!D:E,2,FALSE),0) -> 4 | N31: =_xlfn.IFNA(VLOOKUP(D31,Inputs!G:H,2,FALSE),0) -> 11 | O31: =_xlfn.IFNA(VLOOKUP(D31,Inputs!K:L,2,FALSE),0) -> 12 | P31: 17 | Q31: =(K31-L31)*P31+N31+O31-M31 -> 79.35 | S31: =K31/(VLOOKUP(D31,Inputs!R:S,2,FALSE)+1) -> 4.8571429 | T31: =IF(P31>0,(F31/P31),0) -> 1470.5988 | U31: =(L31*F31) -> 81250.585
B32: CEDD7095 | C32: STELLA FOODS | D32: VEAL | E32: (blank) | F32: 25000 | G32: 6.8 | H32: 170000 | I32: 6 WAY | J32: FAS | K32: =IF(J32="CIF",G32-0.3,G32) -> 6.8 | L32: 3.25 | M32: =_xlfn.IFNA(VLOOKUP(I32,Inputs!D:E,2,FALSE),0) -> 4 | N32: =_xlfn.IFNA(VLOOKUP(D32,Inputs!G:H,2,FALSE),0) -> 11 | O32: =_xlfn.IFNA(VLOOKUP(D32,Inputs!K:L,2,FALSE),0) -> 12 | P32: 17 | Q32: =(K32-L32)*P32+N32+O32-M32 -> 79.35 | S32: =K32/(VLOOKUP(D32,Inputs!R:S,2,FALSE)+1) -> 4.8571429 | T32: =IF(P32>0,(F32/P32),0) -> 1470.5882 | U32: =(L32*F32) -> 81250
B33: CEDD7098 | C33: KARIM OVERSEAS | D33: VEAL | E33: (blank) | F33: 25000 | G33: 6.9 | H33: 172500 | I33: 6 WAY | J33: FAS | K33: =IF(J33="CIF",G33-0.3,G33) -> 6.9 | L33: 3.25 | M33: =_xlfn.IFNA(VLOOKUP(I33,Inputs!D:E,2,FALSE),0) -> 4 | N33: =_xlfn.IFNA(VLOOKUP(D33,Inputs!G:H,2,FALSE),0) -> 11 | O33: =_xlfn.IFNA(VLOOKUP(D33,Inputs!K:L,2,FALSE),0) -> 12 | P33: 17 | Q33: =(K33-L33)*P33+N33+O33-M33 -> 81.05 | S33: =K33/(VLOOKUP(D33,Inputs!R:S,2,FALSE)+1) -> 4.9285714 | T33: =IF(P33>0,(F33/P33),0) -> 1470.5882 | U33: =(L33*F33) -> 81250
B34: CEDD7099 | C34: KARIM OVERSEAS | D34: VEAL | E34: (blank) | F34: 25000 | G34: 6.9 | H34: 172500 | I34: 6 WAY | J34: FAS | K34: =IF(J34="CIF",G34-0.3,G34) -> 6.9 | L34: 3.25 | M34: =_xlfn.IFNA(VLOOKUP(I34,Inputs!D:E,2,FALSE),0) -> 4 | N34: =_xlfn.IFNA(VLOOKUP(D34,Inputs!G:H,2,FALSE),0) -> 11 | O34: =_xlfn.IFNA(VLOOKUP(D34,Inputs!K:L,2,FALSE),0) -> 12 | P34: 17 | Q34: =(K34-L34)*P34+N34+O34-M34 -> 81.05 | S34: =K34/(VLOOKUP(D34,Inputs!R:S,2,FALSE)+1) -> 4.9285714 | T34: =IF(P34>0,(F34/P34),0) -> 1470.5882 | U34: =(L34*F34) -> 81250
B35: CEDD7100 | C35: ALLEGRO | D35: GOAT | E35: (blank) | F35: 18000 | G35: 9.3 | H35: 167400 | I35: CCS | J35: FAS | K35: =IF(J35="CIF",G35-0.3,G35) -> 9.3 | L35: 7.7 | M35: =_xlfn.IFNA(VLOOKUP(I35,Inputs!D:E,2,FALSE),0) -> 2 | N35: =_xlfn.IFNA(VLOOKUP(D35,Inputs!G:H,2,FALSE),0) -> 6 | O35: =_xlfn.IFNA(VLOOKUP(D35,Inputs!K:L,2,FALSE),0) -> 0 | P35: 10 | Q35: =(K35-L35)*P35+N35+O35-M35 -> 20 | S35: =K35/(VLOOKUP(D35,Inputs!R:S,2,FALSE)+1) -> 7.1538462 | T35: =IF(P35>0,(F35/P35),0) -> 1800 | U35: =(L35*F35) -> 138600
B36: Grand Total | F36: =SUM(F5:F35) -> 704096.18 | G36: =(H36/F36) -> 8.8641776 | H36: =SUM(H5:H35) -> 6241233.6
B41: ORDERS LOADED
B44: Row Labels | C44: Customer Name | D44: Type | E44: Loadout Date | F44: Sum of Total QTY | G44: Average of Price AUD | H44: Sum of Amount AUD | I44: Product Type | J44: CIF or FAS ? | K44: NRV (per kg) | L44: Livestock Cost per kg (HSCW) | M44: Pack Cost | N44: Offal Return PH | O44: Avg Skin Return | P44: Avg Weight | Q44: MoM PH | S44: Comments | T44: Do Not Buy Price | U44: Estimated number of heads required | V44: Total Livestock Cost
B45: CED18649 | C45: TIANJIN NAVIGATOR INTERNATIONAL | D45: SHEEP | E45: 46205 | F45: 21617.16 | G45: 9.7101449 | H45: 206907.1 | I45: 6 WAY | J45: CIF | K45: =IF(J45="CIF",G45-0.3,G45) -> 9.4101449 | L45: 8.81 | M45: =_xlfn.IFNA(VLOOKUP(I45,Inputs!D:E,2,FALSE),0) -> 4 | N45: =_xlfn.IFNA(VLOOKUP(D45,Inputs!G:H,2,FALSE),0) -> 8 | O45: =_xlfn.IFNA(VLOOKUP(D45,Inputs!K:L,2,FALSE),0) -> 10 | P45: 24.89 | Q45: =IF(P45>0,(K45-L45)*P45+N45+O45-M45,0) -> 28.937607 | T45: =IF(P45>0,(K45)-((34+M45-O45-N45)/P45),0) -> 8.6066094 | U45: =IF(P45>0,(F45/P45),0) -> 868.50783 | V45: =(L45*F45) -> 190447.18
B46: CED18654 | C46: DALIAN MAGIC INTERNATIONAL | D46: SHEEP | E46: 46212 | F46: 25004.6 | G46: 10.072464 | H46: 248259.96 | I46: 6 WAY | J46: CIF | K46: =IF(J46="CIF",G46-0.3,G46) -> 9.7724638 | L46: 8.21 | M46: =_xlfn.IFNA(VLOOKUP(I46,Inputs!D:E,2,FALSE),0) -> 4 | N46: =_xlfn.IFNA(VLOOKUP(D46,Inputs!G:H,2,FALSE),0) -> 8 | O46: =_xlfn.IFNA(VLOOKUP(D46,Inputs!K:L,2,FALSE),0) -> 10 | P46: 18.24 | Q46: =IF(P46>0,(K46-L46)*P46+N46+O46-M46,0) -> 42.499339 | T46: =IF(P46>0,(K46)-((34+M46-O46-N46)/P46),0) -> 8.6759725 | U46: =IF(P46>0,(F46/P46),0) -> 1370.8662 | V46: =(L46*F46) -> 205287.77
B47: CED18656 | C47: JINAN WELCOME INDUSTRIAL | D47: MUTTON | E47: 46202 | F47: 15503.2 | G47: 9.7101449 | H47: 148387.77 | I47: CCS | J47: CIF | K47: =IF(J47="CIF",G47-0.3,G47) -> 9.4101449 | L47: 7.8 | M47: =_xlfn.IFNA(VLOOKUP(I47,Inputs!D:E,2,FALSE),0) -> 2 | N47: =_xlfn.IFNA(VLOOKUP(D47,Inputs!G:H,2,FALSE),0) -> 8 | O47: =_xlfn.IFNA(VLOOKUP(D47,Inputs!K:L,2,FALSE),0) -> 10 | P47: 23.3 | Q47: =IF(P47>0,(K47-L47)*P47+N47+O47-M47,0) -> 53.516377 | T47: =IF(P47>0,(K47)-((34+M47-O47-N47)/P47),0) -> 8.6376127 | U47: =IF(P47>0,(F47/P47),0) -> 665.37339 | V47: =(L47*F47) -> 120924.96
B48: CEDD7044 | C48: AGRICOMM | D48: VEAL | E48: 46210 | F48: 25008.88 | G48: 6.85 | H48: 171310.83 | I48: 6 WAY | J48: FAS | K48: =IF(J48="CIF",G48-0.3,G48) -> 6.85 | L48: 3.11 | M48: =_xlfn.IFNA(VLOOKUP(I48,Inputs!D:E,2,FALSE),0) -> 4 | N48: =_xlfn.IFNA(VLOOKUP(D48,Inputs!G:H,2,FALSE),0) -> 11 | O48: =_xlfn.IFNA(VLOOKUP(D48,Inputs!K:L,2,FALSE),0) -> 12 | P48: 18.8 | Q48: =IF(P48>0,(K48-L48)*P48+N48+O48-M48,0) -> 89.312 | T48: =IF(P48>0,(K48)-((34+M48-O48-N48)/P48),0) -> 6.0521277 | U48: =IF(P48>0,(F48/P48),0) -> 1330.2596 | V48: =(L48*F48) -> 77777.617
B49: CEDD7060 | C49: AGRICOMM | D49: LAMB | E49: 46206 | F49: 15221.1 | G49: 11.5 | H49: 175042.65 | I49: CCS | J49: FAS | K49: =IF(J49="CIF",G49-0.3,G49) -> 11.5 | L49: 10.35 | M49: =_xlfn.IFNA(VLOOKUP(I49,Inputs!D:E,2,FALSE),0) -> 2 | N49: =_xlfn.IFNA(VLOOKUP(D49,Inputs!G:H,2,FALSE),0) -> 11 | O49: =_xlfn.IFNA(VLOOKUP(D49,Inputs!K:L,2,FALSE),0) -> 10 | P49: 18.06 | Q49: =IF(P49>0,(K49-L49)*P49+N49+O49-M49,0) -> 39.769 | T49: =IF(P49>0,(K49)-((34+M49-O49-N49)/P49),0) -> 10.669435 | U49: =IF(P49>0,(F49/P49),0) -> 842.80731 | V49: =(L49*F49) -> 157538.39
B50: CEDD7067 | C50: MIDFIELD COMMODITIES | D50: VEAL | E50: 46219 | F50: 25000.18 | G50: 6.65 | H50: 166251.2 | I50: 6 WAY | J50: FAS | K50: =IF(J50="CIF",G50-0.3,G50) -> 6.65 | L50: 3.13 | M50: =_xlfn.IFNA(VLOOKUP(I50,Inputs!D:E,2,FALSE),0) -> 4 | N50: =_xlfn.IFNA(VLOOKUP(D50,Inputs!G:H,2,FALSE),0) -> 11 | O50: =_xlfn.IFNA(VLOOKUP(D50,Inputs!K:L,2,FALSE),0) -> 12 | P50: 18.2 | Q50: =IF(P50>0,(K50-L50)*P50+N50+O50-M50,0) -> 83.064 | T50: =IF(P50>0,(K50)-((34+M50-O50-N50)/P50),0) -> 5.8258242 | U50: =IF(P50>0,(F50/P50),0) -> 1373.6363 | V50: =(L50*F50) -> 78250.563
B51: CEDD7070 | C51: SWIFT & COMPANY | D51: LAMB | E51: 46206 | F51: 9836.3 | G51: 11 | H51: 108199.3 | I51: 6 WAY | J51: FAS | K51: =IF(J51="CIF",G51-0.3,G51) -> 11 | L51: 10.18 | M51: =_xlfn.IFNA(VLOOKUP(I51,Inputs!D:E,2,FALSE),0) -> 4 | N51: =_xlfn.IFNA(VLOOKUP(D51,Inputs!G:H,2,FALSE),0) -> 11 | O51: =_xlfn.IFNA(VLOOKUP(D51,Inputs!K:L,2,FALSE),0) -> 10 | P51: 18.34 | Q51: =IF(P51>0,(K51-L51)*P51+N51+O51-M51,0) -> 32.0388 | T51: =IF(P51>0,(K51)-((34+M51-O51-N51)/P51),0) -> 10.073064 | U51: =IF(P51>0,(F51/P51),0) -> 536.33043 | V51: =(L51*F51) -> 100133.53
B52: CEDD7072 | C52: GLOBAL MEAT COMMODITIES | D52: GOAT | E52: 46212 | F52: 24026.78 | G52: 9.75 | H52: 234261.11 | I52: 6 WAY | J52: FAS | K52: =IF(J52="CIF",G52-0.3,G52) -> 9.75 | L52: 8.27 | M52: =_xlfn.IFNA(VLOOKUP(I52,Inputs!D:E,2,FALSE),0) -> 4 | N52: =_xlfn.IFNA(VLOOKUP(D52,Inputs!G:H,2,FALSE),0) -> 6 | O52: =_xlfn.IFNA(VLOOKUP(D52,Inputs!K:L,2,FALSE),0) -> 0 | P52: 16.63 | Q52: =IF(P52>0,(K52-L52)*P52+N52+O52-M52,0) -> 26.6124 | T52: =IF(P52>0,(K52)-((34+M52-O52-N52)/P52),0) -> 7.8257667 | U52: =IF(P52>0,(F52/P52),0) -> 1444.7853 | V52: =(L52*F52) -> 198701.47
B53: CEDD7073 | C53: GLOBAL MEAT COMMODITIES | D53: GOAT | E53: 46226 | F53: 23066.56 | G53: 9.75 | H53: 224898.96 | I53: 6 WAY | J53: FAS | K53: =IF(J53="CIF",G53-0.3,G53) -> 9.75 | L53: 7.93 | M53: =_xlfn.IFNA(VLOOKUP(I53,Inputs!D:E,2,FALSE),0) -> 4 | N53: =_xlfn.IFNA(VLOOKUP(D53,Inputs!G:H,2,FALSE),0) -> 6 | O53: =_xlfn.IFNA(VLOOKUP(D53,Inputs!K:L,2,FALSE),0) -> 0 | P53: 12.64 | Q53: =IF(P53>0,(K53-L53)*P53+N53+O53-M53,0) -> 25.0048 | T53: =IF(P53>0,(K53)-((34+M53-O53-N53)/P53),0) -> 7.2183544 | U53: =IF(P53>0,(F53/P53),0) -> 1824.8861 | V53: =(L53*F53) -> 182917.82
B54: CEDD7084 | C54: BOUNTY FOODS | D54: LAMB | E54: 46227 | F54: 950.75 | G54: 12.2 | H54: 9966.982 | I54: FULL BONE | J54: FAS | K54: =IF(J54="CIF",G54-0.3,G54) -> 12.2 | L54: 10.6 | M54: =_xlfn.IFNA(VLOOKUP(I54,Inputs!D:E,2,FALSE),0) -> 7 | N54: =_xlfn.IFNA(VLOOKUP(D54,Inputs!G:H,2,FALSE),0) -> 11 | O54: =_xlfn.IFNA(VLOOKUP(D54,Inputs!K:L,2,FALSE),0) -> 10 | P54: 15.96 | Q54: =IF(P54>0,(K54-L54)*P54+N54+O54-M54,0) -> 39.536 | T54: =IF(P54>0,(K54)-((34+M54-O54-N54)/P54),0) -> 10.946867 | U54: =IF(P54>0,(F54/P54),0) -> 59.570802 | V54: =(L54*F54) -> 10077.95
B55: CEDD7046 | C55: AGRICOMM | D55: VEAL | E55: 46233 | F55: 25008.58 | G55: 6.85 | H55: =+F55*G55 -> 171308.77 | I55: 6 WAY | J55: FAS | K55: =IF(J55="CIF",G55-0.3,G55) -> 6.85 | L55: 3.2 | M55: =_xlfn.IFNA(VLOOKUP(I55,Inputs!D:E,2,FALSE),0) -> 4 | N55: =_xlfn.IFNA(VLOOKUP(D55,Inputs!G:H,2,FALSE),0) -> 11 | O55: =_xlfn.IFNA(VLOOKUP(D55,Inputs!K:L,2,FALSE),0) -> 12 | P55: 18.2 | Q55: =IF(P55>0,(K55-L55)*P55+N55+O55-M55,0) -> 85.43 | T55: =IF(P55>0,(K55)-((34+M55-O55-N55)/P55),0) -> 6.0258242 | U55: =IF(P55>0,(F55/P55),0) -> 1374.0978 | V55: =(L55*F55) -> 80027.456
B56: CED18673 | C56: TPL FOOD PROCESSING | D56: GOAT | E56: 46233 | F56: 2151.7 | G56: 13.3 | H56: 28617.61 | I56: CCS | J56: CIF | K56: =IF(J56="CIF",G56-0.3,G56) -> 13 | L56: 7.8 | M56: =_xlfn.IFNA(VLOOKUP(I56,Inputs!D:E,2,FALSE),0) -> 2 | N56: =_xlfn.IFNA(VLOOKUP(D56,Inputs!G:H,2,FALSE),0) -> 6 | O56: =_xlfn.IFNA(VLOOKUP(D56,Inputs!K:L,2,FALSE),0) -> 0 | P56: 14.55 | Q56: =IF(P56>0,(K56-L56)*P56+N56+O56-M56,0) -> 79.66 | R56: 16500 | T56: =IF(P56>0,(K56)-((34+M56-O56-N56)/P56),0) -> 10.938144 | U56: =IF(P56>0,(F56/P56),0) -> 147.88316 | V56: =(L56*F56) -> 16783.26
B57: CED18673 | C57: TPL FOOD PROCESSING | D57: LAMB | E57: 46233 | F57: 248.05 | G57: 13.85 | H57: 3435.4925 | I57: CCS | J57: CIF | K57: =IF(J57="CIF",G57-0.3,G57) -> 13.55 | L57: 10.6 | M57: =_xlfn.IFNA(VLOOKUP(I57,Inputs!D:E,2,FALSE),0) -> 2 | N57: =_xlfn.IFNA(VLOOKUP(D57,Inputs!G:H,2,FALSE),0) -> 11 | O57: =_xlfn.IFNA(VLOOKUP(D57,Inputs!K:L,2,FALSE),0) -> 10 | P57: 14 | Q57: =IF(P57>0,(K57-L57)*P57+N57+O57-M57,0) -> 60.3 | R57: 16500 | T57: =IF(P57>0,(K57)-((34+M57-O57-N57)/P57),0) -> 12.478571 | U57: =IF(P57>0,(F57/P57),0) -> 17.717857 | V57: =(L57*F57) -> 2629.33
B58: CED18674 | C58: TPL FOOD PROCESSING | D58: GOAT | E58: 46238 | F58: 1131.73 | G58: 13.3 | H58: 15052.009 | I58: CCS | J58: CIF | K58: =IF(J58="CIF",G58-0.3,G58) -> 13 | L58: 7.9 | M58: =_xlfn.IFNA(VLOOKUP(I58,Inputs!D:E,2,FALSE),0) -> 2 | N58: =_xlfn.IFNA(VLOOKUP(D58,Inputs!G:H,2,FALSE),0) -> 6 | O58: =_xlfn.IFNA(VLOOKUP(D58,Inputs!K:L,2,FALSE),0) -> 0 | P58: 13.23 | Q58: =IF(P58>0,(K58-L58)*P58+N58+O58-M58,0) -> 71.473 | R58: 15734.59 | T58: =IF(P58>0,(K58)-((34+M58-O58-N58)/P58),0) -> 10.732426 | U58: =IF(P58>0,(F58/P58),0) -> 85.542706 | V58: =(L58*F58) -> 8940.667
B59: CED18674 | C59: TPL FOOD PROCESSING | D59: LAMB | E59: 46238 | F59: 149.25 | G59: 13.85 | H59: 2067.1125 | I59: CCS | J59: CIF | K59: =IF(J59="CIF",G59-0.3,G59) -> 13.55 | L59: 10.38 | M59: 2 | N59: =_xlfn.IFNA(VLOOKUP(D59,Inputs!G:H,2,FALSE),0) -> 11 | O59: =_xlfn.IFNA(VLOOKUP(D59,Inputs!K:L,2,FALSE),0) -> 10 | P59: 17.07 | Q59: =IF(P59>0,(K59-L59)*P59+N59+O59-M59,0) -> 73.1119 | R59: 16000 | T59: =IF(P59>0,(K59)-((34+M59-O59-N59)/P59),0) -> 12.671265 | U59: =IF(P59>0,(F59/P59),0) -> 8.7434095 | V59: =(L59*F59) -> 1549.215
B60: CEDD7068 | C60: MIDFIELD COMMODITIES | D60: VEAL | E60: 46240 | F60: 24919.62 | G60: 6.65 | H60: 165715.47 | I60: 6 WAY | J60: FAS | K60: =IF(J60="CIF",G60-0.3,G60) -> 6.65 | L60: 3.37 | M60: =_xlfn.IFNA(VLOOKUP(I60,Inputs!D:E,2,FALSE),0) -> 4 | N60: =_xlfn.IFNA(VLOOKUP(D60,Inputs!G:H,2,FALSE),0) -> 11 | O60: =_xlfn.IFNA(VLOOKUP(D60,Inputs!K:L,2,FALSE),0) -> 12 | P60: 18 | Q60: =IF(P60>0,(K60-L60)*P60+N60+O60-M60,0) -> 78.04 | T60: =IF(P60>0,(K60)-((40+M60-O60-N60)/P60),0) -> 5.4833333 | U60: =IF(P60>0,(F60/P60),0) -> 1384.4233 | V60: =(L60*F60) -> 83979.119
B61: CEDD7047 | C61: AGRICOMM | D61: VEAL | E61: 46244 | F61: 25000.94 | G61: 6.9 | H61: =F61*G61 -> 172506.49 | I61: 6 WAY | J61: FAS | K61: =IF(J61="CIF",G61-0.3,G61) -> 6.9 | L61: 3.36 | M61: =_xlfn.IFNA(VLOOKUP(I61,Inputs!D:E,2,FALSE),0) -> 4 | N61: =_xlfn.IFNA(VLOOKUP(D61,Inputs!G:H,2,FALSE),0) -> 11 | O61: =_xlfn.IFNA(VLOOKUP(D61,Inputs!K:L,2,FALSE),0) -> 12 | P61: 18 | Q61: =IF(P61>0,(K61-L61)*P61+N61+O61-M61,0) -> 82.72 | T61: =IF(P61>0,(K61)-((40+M61-O61-N61)/P61),0) -> 5.7333333 | U61: =IF(P61>0,(F61/P61),0) -> 1388.9411 | V61: =(L61*F61) -> 84003.158
...

Sheet Summary
B2: Cashflow
H3: Weekly Working Capital
I4: 22 | J4: 9.67 | K4: 65000
C5: Avg Sell Price | D5: Avg LV Price | E5: Avg Weight | F5: Skin Return | G5: Heads | H5: Livestock | I5: Direct Labour | J5: VOH | K5: Salaries | L5: Total
B6: Lamb | C6: 11 | D6: 10 | E6: 18 | F6: 10 | G6: 1500 | H6: =(G6*D6*E6) -> 270000 | I6: =($I$4*G6) -> 33000 | J6: =($J$4*G6) -> 14505
B7: Mutton | C7: 9.75 | D7: 9 | E7: 20 | F7: 10 | G7: 1500 | H7: =(G7*D7*E7) -> 270000 | I7: =($I$4*G7) -> 33000 | J7: =($J$4*G7) -> 14505
B8: Goat | C8: 9.6 | D8: 7.9 | E8: 14 | F8: 0 | G8: 2000 | H8: =(G8*D8*E8) -> 221200 | I8: =($I$4*G8) -> 44000 | J8: =($J$4*G8) -> 19340
B9: Veal | C9: 6.85 | D9: 3.2 | E9: 17 | F9: 12.5 | G9: 2800 | H9: =(G9*D9*E9) -> 152320 | I9: =($I$4*G9) -> 61600 | J9: =($J$4*G9) -> 27076
G10: =SUM(G6:G9) -> 7800 | H10: =SUM(H6:H9) -> 913520 | I10: =SUM(I6:I9) -> 171600 | J10: =SUM(J6:J9) -> 75426 | K10: =(K4*1) -> 65000 | L10: =SUM(H10:K10) -> 1225546
E11: 10000
C12: Product | D12: Average Weight (kg) | E12: Number of heads for a 20 ft container
C13: Ovine Brains | D13: 0.12 | E13: =($E$11/D13) -> 83333.333
C14: Ovine Hearts | D14: 0.25 | E14: =($E$11/D14) -> 40000
C15: Ovine Kidneys (pair) | D15: 0.18 | E15: =($E$11/D15) -> 55555.556
C16: Ovine Livers | D16: 0.65 | E16: =($E$11/D16) -> 15384.615
C17: Ovine Lungs | D17: 0.6 | E17: =($E$11/D17) -> 16666.667
C18: Ovine Tongue | D18: 0.18 | E18: =($E$11/D18) -> 55555.556
C19: Ovine Sweetbreads | D19: 0.12 | E19: =($E$11/D19) -> 83333.333
C20: Lamb Runners | D20: 0.84 | E20: =($E$11/D20) -> 11904.762
C25: Assumptions
C26: Weeks to convert livestock to meat | E26: 1
C27: Weeks to convert meat to cash | E27: 2
C28: Weeks to convert skins to cash | E28: 3
C29: Weeks to convert offal to cash | E29: 5
C30: Number of working capital weeks required | E30: 5
C31: Working capital required | E31: =(L10*E30) -> 6127730
B35: Profitability
C37: Expected MOM PH | D37: Direct Labour PH | E37: VOH PH | F37: Gross Margin PH | G37: Gross Margin | H37: FOH Cost PW | I37: EBITDA PW
B38: Lamb | C38: 30 | D38: 19.25 | E38: 9.67 | F38: =(C38-D38-E38) -> 1.08 | G38: =(F38*G6) -> 1620 | H38: =(H42/$G$10)*G6 -> 38680.913 | I38: =(G38-H38) -> -37060.913
B39: Mutton | C39: 30 | D39: 19.25 | E39: 9.67 | F39: =(C39-D39-E39) -> 1.08 | G39: =(F39*G7) -> 1620 | H39: =(H42/$G$10)*G7 -> 38680.913 | I39: =(G39-H39) -> -37060.913
B40: Goat | C40: 30 | D40: 19.25 | E40: 9.67 | F40: =(C40-D40-E40) -> 1.08 | G40: =(F40*G8) -> 2160 | H40: =(H42/$G$10)*G8 -> 51574.551 | I40: =(G40-H40) -> -49414.551
B41: Veal | C41: 76.4 | D41: 19.25 | E41: 9.67 | F41: =(C41-D41-E41) -> 47.48 | G41: =(F41*G9) -> 132944 | H41: =(H42/$G$10)*G9 -> 72204.372 | I41: =(G41-H41) -> 60739.628
F42: =(G42/G10) -> 17.73641 | G42: =SUM(G38:G41) -> 138344 | H42: =(804563/4) -> 201140.75 | I42: =(G42-H42) -> -62796.75
B46: Incresing revenue
B48: Additional Offal collection
B50: Offal Type | C50: NRV
B51: Brains | C51: 1.64
B52: Hocks | C52: 2
C53: =(C51*G6) -> 2460
C54: =(C52)*(G6+G7) -> 6000
...

Sheet Offal
E1: 3000
B2: Product | C2: Average Weight (kg) | D2: Number of heads for a 20 ft container | E2: Weight of a load | F2: Wks for a load | G2: Revenue per head
B3: Ovine Brains | C3: 0.12 | D3: 83333.333 | E3: 800 | F3: =(E3/C3)/$E$1 -> 2.2222222 | H3: 1.65
B4: Ovine Hearts | C4: 0.25 | D4: 40000 | E4: 800 | F4: =(E4/C4)/$E$1 -> 1.0666667 | G4: 1.47
B5: Ovine Kidneys (pair) | C5: 0.18 | D5: 55555.556 | E5: 800 | F5: =(E5/C5)/$E$1 -> 1.4814815 | G5: 0.84
B6: Ovine Livers | C6: 0.65 | D6: 15384.615 | E6: 800 | F6: =(E6/C6)/$E$1 -> 0.41025641 | G6: 2.1
B7: Ovine Lungs | C7: 0.6 | D7: 16666.667 | E7: 800 | F7: =(E7/C7)/$E$1 -> 0.44444444 | G7: 1.62
B8: Ovine Tongue | C8: 0.18 | D8: 55555.556 | E8: 800 | F8: =(E8/C8)/$E$1 -> 1.4814815 | G8: 1.56
B9: Ovine Sweetbreads | C9: 0.12 | D9: 83333.333 | E9: 800 | F9: =(E9/C9)/$E$1 -> 2.2222222 | H9: 1.44
B10: Lamb Runners | C10: 0.84 | D10: 11904.762 | E10: 10000 | F10: =(E10/C10)/$E$1 -> 3.968254 | G10: 4.38
G11: =SUM(G3:G10) -> 11.97

Sheet Veal
A1: VEAL KILLED FROM 1ST JULY 2024 TO PRESENT
A2: Date | B2: No. of Heads Killed | G2: Week | H2: Heads | I2: Month
A3: 45474 | B3: 266 | C3: =WEEKNUM(A3,2) -> 27 | D3: =TEXT(A3,"mmm") -> Jul | G3: 27 | H3: =SUMIF(C:C,G3,B:B) -> 1414 | I3: =VLOOKUP(G3,C:D,2,FALSE) -> Jul
A4: 45475 | B4: 130 | C4: =WEEKNUM(A4,2) -> 27 | D4: =TEXT(A4,"mmm") -> Jul | G4: 28 | H4: =SUMIF(C:C,G4,B:B) -> 1791 | I4: =VLOOKUP(G4,C:D,2,FALSE) -> Jul
A5: 45476 | B5: 63 | C5: =WEEKNUM(A5,2) -> 27 | D5: =TEXT(A5,"mmm") -> Jul | G5: 29 | H5: =SUMIF(C:C,G5,B:B) -> 1384 | I5: =VLOOKUP(G5,C:D,2,FALSE) -> Jul
A6: 45477 | B6: 392 | C6: =WEEKNUM(A6,2) -> 27 | D6: =TEXT(A6,"mmm") -> Jul | G6: 30 | H6: =SUMIF(C:C,G6,B:B) -> 1819 | I6: =VLOOKUP(G6,C:D,2,FALSE) -> Jul
A7: 45478 | B7: 23 | C7: =WEEKNUM(A7,2) -> 27 | D7: =TEXT(A7,"mmm") -> Jul | G7: 31 | H7: =SUMIF(C:C,G7,B:B) -> 2256 | I7: =VLOOKUP(G7,C:D,2,FALSE) -> Jul
A8: 45481 | B8: 314 | C8: =WEEKNUM(A8,2) -> 28 | D8: =TEXT(A8,"mmm") -> Jul | G8: 32 | H8: =SUMIF(C:C,G8,B:B) -> 3248 | I8: =VLOOKUP(G8,C:D,2,FALSE) -> Aug
A9: 45482 | B9: 243 | C9: =WEEKNUM(A9,2) -> 28 | D9: =TEXT(A9,"mmm") -> Jul | G9: 33 | H9: =SUMIF(C:C,G9,B:B) -> 4761 | I9: =VLOOKUP(G9,C:D,2,FALSE) -> Aug
A10: 45483 | B10: 64 | C10: =WEEKNUM(A10,2) -> 28 | D10: =TEXT(A10,"mmm") -> Jul | G10: 34 | H10: =SUMIF(C:C,G10,B:B) -> 8106 | I10: =VLOOKUP(G10,C:D,2,FALSE) -> Aug
A11: 45484 | B11: 378 | C11: =WEEKNUM(A11,2) -> 28 | D11: =TEXT(A11,"mmm") -> Jul | G11: 35 | H11: =SUMIF(C:C,G11,B:B) -> 8315 | I11: =VLOOKUP(G11,C:D,2,FALSE) -> Aug
A12: 45485 | B12: 107 | C12: =WEEKNUM(A12,2) -> 28 | D12: =TEXT(A12,"mmm") -> Jul | G12: 36 | H12: =SUMIF(C:C,G12,B:B) -> 6858 | I12: =VLOOKUP(G12,C:D,2,FALSE) -> Sep
A13: 45488 | B13: 406 | C13: =WEEKNUM(A13,2) -> 29 | D13: =TEXT(A13,"mmm") -> Jul | G13: 37 | H13: =SUMIF(C:C,G13,B:B) -> 6561 | I13: =VLOOKUP(G13,C:D,2,FALSE) -> Sep
A14: 45489 | B14: 249 | C14: =WEEKNUM(A14,2) -> 29 | D14: =TEXT(A14,"mmm") -> Jul | G14: 38 | H14: =SUMIF(C:C,G14,B:B) -> 4893 | I14: =VLOOKUP(G14,C:D,2,FALSE) -> Sep
... A19: 45496 | B19: 274 | C19: =WEEKNUM(A19,2) -> 30 | D19: =TEXT(A19,"mmm") -> Jul | G19: 43 | H19: =SUMIF(C:C,G19,B:B) -> 1509 | I19: =VLOOKUP(G19,C:D,2,FALSE) -> Oct
A20: 45497 | B20: 216 | C20: =WEEKNUM(A20,2) -> 30 | D20: =TEXT(A20,"mmm") -> Jul
A21: 45498 | B21: 594 | C21: =WEEKNUM(A21,2) -> 30 | D21: =TEXT(A21,"mmm") -> Jul
A22: 45499 | B22: 347 | C22: =WEEKNUM(A22,2) -> 30 | D22: =TEXT(A22,"mmm") -> Jul
A23: 45502 | B23: 670 | C23: =WEEKNUM(A23,2) -> 31 | D23: =TEXT(A23,"mmm") -> Jul
A24: 45503 | B24: 368 | C24: =WEEKNUM(A24,2) -> 31 | D24: =TEXT(A24,"mmm") -> Jul
A25: 45504 | B25: 224 | C25: =WEEKNUM(A25,2) -> 31 | D25: =TEXT(A25,"mmm") -> Jul
A26: 45505 | B26: 601 | C26: =WEEKNUM(A26,2) -> 31 | D26: =TEXT(A26,"mmm") -> Aug
A27: 45506 | B27: 393 | C27: =WEEKNUM(A27,2) -> 31 | D27: =TEXT(A27,"mmm") -> Aug
A28: 45509 | B28: 1047 | C28: =WEEKNUM(A28,2) -> 32 | D28: =TEXT(A28,"mmm") -> Aug
A29: 45510 | B29: 473 | C29: =WEEKNUM(A29,2) -> 32 | D29: =TEXT(A29,"mmm") -> Aug
A30: 45511 | B30: 196 | C30: =WEEKNUM(A30,2) -> 32 | D30: =TEXT(A30,"mmm") -> Aug
A31: 45512 | B31: 983 | C31: =WEEKNUM(A31,2) -> 32 | D31: =TEXT(A31,"mmm") -> Aug
... A347: 46185 | B347: 79 | C347: =WEEKNUM(A347,2) -> 24 | D347: =TEXT(A347,"mmm") -> Jun

Sheet Financial Data
A2: Sales Representative | B2: Peter
A3: Status | B3: (Multiple Items)
A5: Row Labels | B5: Customer Name | C5: Type | D5: Loadout Date | E5: Sum of Total QTY | F5: Average of Price AUD | G5: Sum of Amount AUD | H5: CIF or FAS ? | I5: Ranking | J5: CIF | N5: profit Ranking | O5: Profit Band | P5: Estimated Margin at livestock level | Q5: Do not buy price | R5: Post production analysis
A6: CED18649 | B6: TIANJIN NAVIGATOR INTERNATIONAL | C6: SHEEP | D6: 46205 | E6: 23000 | F6: 9.7101449 | G6: 220142.86 | H6: CIF | I6: A | J6: =+F6-0.4 -> 9.3101449 | N6: 4 | O6: C
A7: CED18650 | B7: SHANGHAI NEW SOURCE | C7: SHEEP | D7: (blank) | E7: 25000 | F7: 10.144928 | G7: 250000 | H7: CIF | I7: A | J7: =+F7-0.4 -> 9.7449275 | N7: 3 | O7: B | P7: 3 | Q7: $3.50 FOR VEAL
A8: CED18651 | B8: SHANGHAI NEW SOURCE | C8: SHEEP | D8: (blank) | E8: 25000 | F8: 10.144928 | G8: 250000 | H8: CIF | I8: A | J8: =+F8-0.4 -> 9.7449275 | N8: 2 | O8: B | P8: 1.5 | Q8: $8.30 FOR GOATS
A9: CED18653 | B9: DALIAN MAGIC INTERNATIONAL | C9: SHEEP | D9: (blank) | E9: 22000 | F9: 9.7101449 | G9: 210571.43 | H9: CIF | I9: A | J9: =+F9-0.4 -> 9.3101449 | N9: 1 | O9: A | P9: 0.8 | Q9: $11.00 FOR LAMBS
A10: CED18654 | B10: DALIAN MAGIC INTERNATIONAL | C10: SHEEP | D10: (blank) | E10: 25000 | F10: 10.072464 | G10: 248214.29 | H10: CIF | I10: A | J10: =+F10-0.4 -> 9.6724638 | N10: 5 | O10: c | P10: 0.8 | Q10: $9.30 FOR MUTTON
A11: CED18655 | B11: DALIAN MAGIC INTERNATIONAL | C11: SHEEP | D11: (blank) | E11: 25000 | F11: 10.072464 | G11: 248214.29 | H11: CIF | I11: A | J11: =+F11-0.4 -> 9.6724638 | N11: 6 | O11: c
A12: CED18656 | B12: JINAN WELCOME INDUSTRIAL | C12: MUTTON | D12: 46202 | E12: 15503.2 | F12: 9.7101449 | G12: 148387.77 | H12: CIF | I12: C | J12: =+F12-0.4 -> 9.3101449 | N12: 7 | O12: c
A13: CED18658 | B13: CHONGQING GOUZHAN INDUSTRIAL | C13: GOAT | D13: (blank) | E13: 24999 | F13: 10 | G13: 246418.71 | H13: CIF | I13: A | J13: =+F13-0.4 -> 9.6 | N13: 13 | O13: c
A14: CED18659 | B14: CHONGQING GOUZHAN INDUSTRIAL | C14: GOAT | D14: (blank) | E14: 24999 | F14: 10 | G14: 246418.71 | H14: CIF | I14: A | J14: =+F14-0.4 -> 9.6 | N14: 9 | O14: c
A15: CED18660 | B15: SHENZHEN YUESHI SUPPLY | C15: GOAT | D15: (blank) | E15: 24999 | F15: 10 | G15: 246418.71 | H15: CIF | I15: A | J15: =+F15-0.4 -> 9.6
A16: CED18662 | B16: CHONGQING GOUZHAN INDUSTRIAL | C16: GOAT | D16: (blank) | E16: 17000 | F16: 10.289855 | G16: 172428.57 | H16: CIF | I16: A | J16: =+F16-0.4 -> 9.8898551
A17: CED18663 | B17: SHENZHEN YUESHI SUPPLY | C17: SHEEP | D17: (blank) | E17: 25000 | F17: 9.8550725 | G17: 242857.14 | H17: CIF | I17: A | J17: =+F17-0.4 -> 9.4550725
A18: CED18664 | B18: SHENZHEN YUESHI SUPPLY | C18: SHEEP | D18: (blank) | E18: 25000 | F18: 9.8550725 | G18: 242857.14 | H18: CIF | I18: A | J18: =+F18-0.4 -> 9.4550725
A19: CEDD6957 | B19: SURE GOOD FOODS | C19: GOAT | D19: (blank) | E19: 24999 | F19: 8.4 | G19: 209991.6 | H19: FAS | I19: C | J19: FAS
A20: CEDD7044 | B20: AGRICOMM | C20: VEAL | D20: (blank) | E20: 25000 | F20: 6.85 | G20: 171250 | H20: FAS | I20: A | J20: FAS
A21: CEDD7045 | B21: AGRICOMM | C21: VEAL | D21: (blank) | E21: 25000 | F21: 6.85 | G21: 171250 | H21: FAS | I21: A | J21: FAS
A22: CEDD7046 | B22: AGRICOMM | C22: VEAL | D22: (blank) | E22: 25000 | F22: 6.85 | G22: 171250 | H22: FAS | I22: A | J22: FAS | N22: Profit Ranking (Peter) | O22: All orders to be ranked from 1 to n , 1 being the most profitable
A23: CEDD7047 | B23: AGRICOMM | C23: VEAL | D23: (blank) | E23: 25000 | F23: 6.85 | G23: 171250 | H23: FAS | I23: A | J23: FAS | N23: Profit Band (Peter) | O23: Only 3 bands A , B , C . A being highly protable B just about profitable C loss making Please set the band metrics Please attached calculation
A24: CEDD7048 | B24: AGRICOMM | C24: VEAL | D24: (blank) | E24: 25000 | F24: 6.85 | G24: 171250 | H24: FAS | I24: A | J24: FAS | N24: Estimated Margin (Peter) | O24: This is sales achieved less livestock cost plus transport ie livestock at the plant exclude offals and skins (Calculation to be attached)
A25: CEDD7049 | B25: AGRICOMM | C25: VEAL | D25: (blank) | E25: 25000 | F25: 6.85 | G25: 171250 | H25: FAS | I25: A | J25: FAS | N25: Do NOT Buy price (Peter) | O25: Buyer cannot buy anything above this price. Buyer must attempt to achieve below ths do not buy price
A26: CEDD7050 | B26: AGRICOMM | C26: VEAL | D26: (blank) | E26: 25000 | F26: 6.85 | G26: 171250 | H26: FAS | I26: A | J26: FAS | N26: Post production analysis | O26: This calculate the actual margin at actual livestock price and actual transport cost exclude offals and skins This will be compared with Estimated Margin . Calculation to bde attached
A27: CEDD7057 | B27: STELLA FOODS | C27: GOAT | D27: (blank) | E27: 24999 | F27: 9.5 | G27: 237490.5 | H27: FAS | I27: B | J27: FAS | N27: Note | O27: All of this analysis exclude offals and skins but include transport cost
A28: CEDD7060 | B28: AGRICOMM | C28: LAMB | D28: 46206 | E28: 17000 | F28: 11.5 | G28: 195500 | H28: FAS | I28: B | J28: FAS
A29: CEDD7062 | B29: STELLA FOODS | C29: LAMB | D29: (blank) | E29: 17000 | F29: 11.6 | G29: 197200 | H29: FAS | I29: A | J29: FAS
A30: CEDD7063 | B30: STELLA FOODS | C30: LAMB | D30: (blank) | E30: 17000 | F30: 11.6 | G30: 197200 | H30: FAS | I30: A | J30: FAS
A31: CEDD7065 | B31: AGRICOMM | C31: GOAT | D31: (blank) | E31: 25000 | F31: 9.8 | G31: 245000 | H31: FAS | I31: A | J31: FAS
A32: CEDD7067 | B32: MIDFIELD COMMODITIES | C32: VEAL | D32: (blank) | E32: 25000 | F32: 6.65 | G32: 166250 | H32: FAS | I32: A | J32: FAS
A33: CEDD7068 | B33: MIDFIELD COMMODITIES | C33: VEAL | D33: (blank) | E33: 25000 | F33: 6.65 | G33: 166250 | H33: FAS | I33: A | J33: FAS
A34: CEDD7069 | B34: GLOBAL MEAT COMMODITIES | C34: GOAT | D34: (blank) | E34: 24000 | F34: 9.65 | G34: 231600 | H34: FAS | I34: B | J34: FAS
A35: CEDD7070 | B35: SWIFT & COMPANY | C35: LAMB | D35: 46206 | E35: 10000 | F35: 11 | G35: 110000 | H35: FAS | I35: A | J35: FAS
A36: CEDD7072 | B36: GLOBAL MEAT COMMODITIES | C36: GOAT | D36: (blank) | E36: 24000 | F36: 9.75 | G36: 234000 | H36: FAS | I36: A | J36: FAS
A37: CEDD7073 | B37: GLOBAL MEAT COMMODITIES | C37: GOAT | D37: (blank) | E37: 24000 | F37: 9.75 | G37: 234000 | H37: FAS | I37: A | J37: FAS
A38: CED18669 | B38: CHONGQING GOUZHAN INDUSTRIAL | C38: GOAT | D38: (blank) | E38: 16000 | F38: 10.072464 | G38: 158857.14 | H38: CIF | I38: A | J38: =+F38-0.4 -> 9.6724638
A39: CED18670 | B39: CHONGQING GOUZHAN INDUSTRIAL | C39: GOAT | D39: (blank) | E39: 16000 | F39: 10.144928 | G39: 160000 | H39: CIF | I39: A | J39: =+F39-0.4 -> 9.7449275
A40: CEDD7076 | B40: GLOBAL MEAT COMMODITIES | C40: GOAT | D40: (blank) | E40: 24000 | F40: 9.75 | G40: 234000 | H40: CIF | I40: A | J40: FAS
A41: Grand Total | E41: 791498.2 | F41: 8.5489942 | G41: 7149018.9

Sheet Inputs
G2: Offal | K2: Skins
B3: CIF | D3: CCS | E3: 2 | G3: SHEEP | H3: 8 | K3: SHEEP | L3: 10 | O3: SHEEP | P3: 22 | R3: Required Margins
B4: FAS | D4: 6 Way | E4: 4 | G4: MUTTON | H4: 8 | K4: MUTTON | L4: 10 | O4: MUTTON | P4: 24
D5: Full Bone | E5: 7 | G5: GOAT | H5: 6 | K5: GOAT | L5: 0 | O5: GOAT | P5: 14 | R5: SHEEP | S5: 0.2 | T5: Provided by the financier
G6: VEAL | H6: 11 | K6: VEAL | L6: 12 | O6: VEAL | P6: 17 | R6: GOAT | S6: 0.3
G7: LAMB | H7: 11 | K7: LAMB | L7: 10 | O7: LAMB | P7: 19 | R7: VEAL | S7: 0.4
R8: LAMB | S8: 0.2
B11: A being highly protable B just about profitable C loss making
