Workbook

Sheet Profitability Analysis
X1: Sheep | Y1: 22 | AC1: 0.83 | AD1: *Based on buying price
X2: Lamb | Y2: 18 | AC2: 0.83 | AD2: *Based on buying price
X3: Goat | Y3: 14 | AC3: 0.77 | AD3: *Based on buying price
X4: Veal | Y4: 17 | AC4: 0.5
B5: ACTIVE ORDERS AS OF 30/07 | I5: Janeth to update | L5: Pete to update | P5: Pete to update | X5: 0.3 | Z5: 3
B7: Row Labels | C7: Customer Name | D7: Type | E7: Loadout Date | F7: Sum of Total QTY | G7: Average of Price AUD | H7: Sum of Amount AUD | I7: Product Type | J7: CIF or FAS ? | K7: NRV (per kg) | L7: Livestock Cost per kg (HSCW) | M7: Pack Cost | N7: Offal Return PH | O7: Avg Skin Return | P7: Avg Weight | Q7: MoM PH | R7: Deposit Received | S7: Comments | T7: Do Not Buy Price | U7: Estimated number of heads required | V7: Total Livestock Cost | X7: Average of Price AUD | Y7: Pack Cost | Z7: Offal Return PH | AA7: Avg Skin Return | AB7: Profit On Peter Costs | AC7: Bing Do Not Buy Price | AD7: Profit On Bing Do Not Buy Price | AE7: Diff VS Gayan | AF7: Diff VS Peter
B8: CED18650 | C8: SHANGHAI NEW SOURCE | D8: SHEEP | E8: (blank) | F8: 25000 | G8: 10.144928 | H8: 250000 | I8: 6 WAY | J8: CIF | K8: =IF(J8="CIF",G8-0.3,G8) -> 9.8449275 | L8: 8.4 | M8: =_xlfn.IFNA(VLOOKUP(I8,Sheet1!D:E,2,FALSE),0) -> 4 | N8: =_xlfn.IFNA(VLOOKUP(D8,Sheet1!G:H,2,FALSE),0) -> 8 | O8: =_xlfn.IFNA(VLOOKUP(D8,Sheet1!K:L,2,FALSE),0) -> 10 | P8: 22 | Q8: =IF(P8>0,(K8-L8)*P8+N8+O8-M8,0) -> 45.788406 | R8: =197005.8/2 -> 98502.9 | T8: =IF(P8>0,(K8)-((40+M8-O8-N8)/P8),0) -> 8.6631094 | U8: =IF(P8>0,(F8/P8),0) -> 1136.3636 | V8: =(L8*F8) -> 210000 | X8: =$G8-$X$5 -> 9.8449275 | Y8: =$M8/VLOOKUP($D8,$X$1:$Y$4,2,0) -> 0.18181818 | Z8: =$N8/VLOOKUP($D8,$X$1:$Y$4,2,0) -> 0.36363636 | AA8: =$O8/VLOOKUP($D8,$X$1:$Y$4,2,0) -> 0.45454545 | AB8: =X8-L8-Y8+Z8+AA8 -> 2.0812912 | AC8: =$X8*VLOOKUP($D8,$X$1:$AC$4,6,0) -> 8.1712899 | AD8: =X8-AC8-Y8+Z8+AA8 -> 2.3100013 | AE8: =AC8-T8 -> -0.4918195 | AF8: =AC8-L8 -> -0.22871014
B9: CED18651 | C9: SHANGHAI NEW SOURCE | D9: SHEEP | E9: (blank) | F9: 25000 | G9: 10.144928 | H9: 250000 | I9: 6 WAY | J9: CIF | K9: =IF(J9="CIF",G9-0.3,G9) -> 9.8449275 | L9: 8.4 | M9: =_xlfn.IFNA(VLOOKUP(I9,Sheet1!D:E,2,FALSE),0) -> 4 | N9: =_xlfn.IFNA(VLOOKUP(D9,Sheet1!G:H,2,FALSE),0) -> 8 | O9: =_xlfn.IFNA(VLOOKUP(D9,Sheet1!K:L,2,FALSE),0) -> 10 | P9: 22 | Q9: =IF(P9>0,(K9-L9)*P9+N9+O9-M9,0) -> 45.788406 | R9: =197005.8/2 -> 98502.9 | T9: =IF(P9>0,(K9)-((40+M9-O9-N9)/P9),0) -> 8.6631094 | U9: =IF(P9>0,(F9/P9),0) -> 1136.3636 | V9: =(L9*F9) -> 210000 | X9: =$G9-$X$5 -> 9.8449275 | Y9: =$M9/VLOOKUP($D9,$X$1:$Y$4,2,0) -> 0.18181818 | Z9: =$N9/VLOOKUP($D9,$X$1:$Y$4,2,0) -> 0.36363636 | AA9: =$O9/VLOOKUP($D9,$X$1:$Y$4,2,0) -> 0.45454545 | AB9: =X9-L9-Y9+Z9+AA9 -> 2.0812912 | AC9: =$X9*VLOOKUP($D9,$X$1:$AC$4,6,0) -> 8.1712899 | AD9: =X9-AC9-Y9+Z9+AA9 -> 2.3100013 | AE9: =AC9-T9 -> -0.4918195 | AF9: =AC9-L9 -> -0.22871014
B10: CED18653 | C10: DALIAN MAGIC INTERNATIONAL | D10: SHEEP | E10: (blank) | F10: 22000 | G10: 9.7101449 | H10: 210571.43 | I10: 6 WAY | J10: CIF | K10: =IF(J10="CIF",G10-0.3,G10) -> 9.4101449 | L10: 8.4 | M10: =_xlfn.IFNA(VLOOKUP(I10,Sheet1!D:E,2,FALSE),0) -> 4 | N10: =_xlfn.IFNA(VLOOKUP(D10,Sheet1!G:H,2,FALSE),0) -> 8 | O10: =_xlfn.IFNA(VLOOKUP(D10,Sheet1!K:L,2,FALSE),0) -> 10 | P10: 28 | Q10: =IF(P10>0,(K10-L10)*P10+N10+O10-M10,0) -> 42.284058 | T10: =IF(P10>0,(K10)-((40+M10-O10-N10)/P10),0) -> 8.4815735 | U10: =IF(P10>0,(F10/P10),0) -> 785.71429 | V10: =(L10*F10) -> 184800 | X10: =$G10-$X$5 -> 9.4101449 | Y10: =$M10/VLOOKUP($D10,$X$1:$Y$4,2,0) -> 0.18181818 | Z10: =$N10/VLOOKUP($D10,$X$1:$Y$4,2,0) -> 0.36363636 | AA10: =$O10/VLOOKUP($D10,$X$1:$Y$4,2,0) -> 0.45454545 | AB10: =X10-L10-Y10+Z10+AA10 -> 1.6465086 | AC10: =$X10*VLOOKUP($D10,$X$1:$AC$4,6,0) -> 7.8104203 | AD10: =X10-AC10-Y10+Z10+AA10 -> 2.2360883 | AE10: =AC10-T10 -> -0.67115321 | AF10: =AC10-L10 -> -0.58957971
B11: CED18655 | C11: DALIAN MAGIC INTERNATIONAL | D11: SHEEP | E11: (blank) | F11: 25000 | G11: 10.072464 | H11: 248214.29 | I11: 6 WAY | J11: CIF | K11: =IF(J11="CIF",G11-0.3,G11) -> 9.7724638 | L11: 8.4 | M11: =_xlfn.IFNA(VLOOKUP(I11,Sheet1!D:E,2,FALSE),0) -> 4 | N11: =_xlfn.IFNA(VLOOKUP(D11,Sheet1!G:H,2,FALSE),0) -> 8 | O11: =_xlfn.IFNA(VLOOKUP(D11,Sheet1!K:L,2,FALSE),0) -> 10 | P11: 22 | Q11: =IF(P11>0,(K11-L11)*P11+N11+O11-M11,0) -> 44.194203 | T11: =IF(P11>0,(K11)-((40+M11-O11-N11)/P11),0) -> 8.5906456 | U11: =IF(P11>0,(F11/P11),0) -> 1136.3636 | V11: =(L11*F11) -> 210000 | X11: =$G11-$X$5 -> 9.7724638 | Y11: =$M11/VLOOKUP($D11,$X$1:$Y$4,2,0) -> 0.18181818 | Z11: =$N11/VLOOKUP($D11,$X$1:$Y$4,2,0) -> 0.36363636 | AA11: =$O11/VLOOKUP($D11,$X$1:$Y$4,2,0) -> 0.45454545 | AB11: =X11-L11-Y11+Z11+AA11 -> 2.0088274 | AC11: =$X11*VLOOKUP($D11,$X$1:$AC$4,6,0) -> 8.1111449 | AD11: =X11-AC11-Y11+Z11+AA11 -> 2.2976825 | AE11: =AC11-T11 -> -0.47950066 | AF11: =AC11-L11 -> -0.28885507
B12: CED18658 | C12: CHONGQING GOUZHAN INDUSTRIAL | D12: GOAT | E12: (blank) | F12: 24999 | G12: 10 | H12: 246418.71 | I12: 6 WAY | J12: CIF | K12: =IF(J12="CIF",G12-0.3,G12) -> 9.7 | L12: 7.7 | M12: =_xlfn.IFNA(VLOOKUP(I12,Sheet1!D:E,2,FALSE),0) -> 4 | N12: =_xlfn.IFNA(VLOOKUP(D12,Sheet1!G:H,2,FALSE),0) -> 6 | O12: 0.5 | P12: 14 | Q12: =IF(P12>0,(K12-L12)*P12+N12+O12-M12,0) -> 30.5 | R12: =240755.99/2 -> 120377.99 | T12: =IF(P12>0,(K12)-((40+M12-O12-N12)/P12),0) -> 7.0214286 | U12: =IF(P12>0,(F12/P12),0) -> 1785.6429 | V12: =(L12*F12) -> 192492.3 | X12: =$G12-$X$5 -> 9.7 | Y12: =$M12/VLOOKUP($D12,$X$1:$Y$4,2,0) -> 0.28571429 | Z12: =$N12/VLOOKUP($D12,$X$1:$Y$4,2,0) -> 0.42857143 | AA12: =$O12/VLOOKUP($D12,$X$1:$Y$4,2,0) -> 0.035714286 | AB12: =X12-L12-Y12+Z12+AA12 -> 2.1785714 | AC12: =$X12*VLOOKUP($D12,$X$1:$AC$4,6,0) -> 7.469 | AD12: =X12-AC12-Y12+Z12+AA12 -> 2.4095714 | AE12: =AC12-T12 -> 0.44757143 | AF12: =AC12-L12 -> -0.231
B13: CED18659 | C13: CHONGQING GOUZHAN INDUSTRIAL | D13: GOAT | E13: (blank) | F13: 24999 | G13: 10 | H13: 246418.71 | I13: 6 WAY | J13: CIF | K13: =IF(J13="CIF",G13-0.3,G13) -> 9.7 | L13: 7.7 | M13: =_xlfn.IFNA(VLOOKUP(I13,Sheet1!D:E,2,FALSE),0) -> 4 | N13: =_xlfn.IFNA(VLOOKUP(D13,Sheet1!G:H,2,FALSE),0) -> 6 | O13: 0.5 | P13: 14 | Q13: =IF(P13>0,(K13-L13)*P13+N13+O13-M13,0) -> 30.5 | R13: =240755.99/2 -> 120377.99 | T13: =IF(P13>0,(K13)-((40+M13-O13-N13)/P13),0) -> 7.0214286 | U13: =IF(P13>0,(F13/P13),0) -> 1785.6429 | V13: =(L13*F13) -> 192492.3 | X13: =$G13-$X$5 -> 9.7 | Y13: =$M13/VLOOKUP($D13,$X$1:$Y$4,2,0) -> 0.28571429 | Z13: =$N13/VLOOKUP($D13,$X$1:$Y$4,2,0) -> 0.42857143 | AA13: =$O13/VLOOKUP($D13,$X$1:$Y$4,2,0) -> 0.035714286 | AB13: =X13-L13-Y13+Z13+AA13 -> 2.1785714 | AC13: =$X13*VLOOKUP($D13,$X$1:$AC$4,6,0) -> 7.469 | AD13: =X13-AC13-Y13+Z13+AA13 -> 2.4095714 | AE13: =AC13-T13 -> 0.44757143 | AF13: =AC13-L13 -> -0.231
B14: CED18660 | C14: SHENZHEN YUESHI SUPPLY | D14: GOAT | E14: (blank) | F14: 24999 | G14: 10 | H14: 246418.71 | I14: 6 WAY | J14: CIF | K14: =IF(J14="CIF",G14-0.3,G14) -> 9.7 | L14: 7.7 | M14: =_xlfn.IFNA(VLOOKUP(I14,Sheet1!D:E,2,FALSE),0) -> 4 | N14: =_xlfn.IFNA(VLOOKUP(D14,Sheet1!G:H,2,FALSE),0) -> 6 | O14: 0.5 | P14: 14 | Q14: =IF(P14>0,(K14-L14)*P14+N14+O14-M14,0) -> 30.5 | R14: 72124.63 | T14: =IF(P14>0,(K14)-((40+M14-O14-N14)/P14),0) -> 7.0214286 | U14: =IF(P14>0,(F14/P14),0) -> 1785.6429 | V14: =(L14*F14) -> 192492.3 | X14: =$G14-$X$5 -> 9.7 | Y14: =$M14/VLOOKUP($D14,$X$1:$Y$4,2,0) -> 0.28571429 | Z14: =$N14/VLOOKUP($D14,$X$1:$Y$4,2,0) -> 0.42857143 | AA14: =$O14/VLOOKUP($D14,$X$1:$Y$4,2,0) -> 0.035714286 | AB14: =X14-L14-Y14+Z14+AA14 -> 2.1785714 | AC14: =$X14*VLOOKUP($D14,$X$1:$AC$4,6,0) -> 7.469 | AD14: =X14-AC14-Y14+Z14+AA14 -> 2.4095714 | AE14: =AC14-T14 -> 0.44757143 | AF14: =AC14-L14 -> -0.231
B15: CED18662 | C15: CHONGQING GOUZHAN INDUSTRIAL | D15: GOAT | E15: (blank) | F15: 17000 | G15: 10.289855 | H15: 172428.57 | I15: CCS | J15: CIF | K15: =IF(J15="CIF",G15-0.3,G15) -> 9.9898551 | L15: 7.7 | M15: =_xlfn.IFNA(VLOOKUP(I15,Sheet1!D:E,2,FALSE),0) -> 2 | N15: =_xlfn.IFNA(VLOOKUP(D15,Sheet1!G:H,2,FALSE),0) -> 6 | O15: 0.5 | P15: 10 | Q15: =IF(P15>0,(K15-L15)*P15+N15+O15-M15,0) -> 27.398551 | R15: 171364.63 | S15: 9 Ton Loaded | T15: =IF(P15>0,(K15)-((40+M15-O15-N15)/P15),0) -> 6.4398551 | U15: =IF(P15>0,(F15/P15),0) -> 1700 | V15: =(L15*F15) -> 130900 | X15: =$G15-$X$5 -> 9.9898551 | Y15: =$M15/VLOOKUP($D15,$X$1:$Y$4,2,0) -> 0.14285714 | Z15: =$N15/VLOOKUP($D15,$X$1:$Y$4,2,0) -> 0.42857143 | AA15: =$O15/VLOOKUP($D15,$X$1:$Y$4,2,0) -> 0.035714286 | AB15: =X15-L15-Y15+Z15+AA15 -> 2.6112836 | AC15: =$X15*VLOOKUP($D15,$X$1:$AC$4,6,0) -> 7.6921884 | AD15: =X15-AC15-Y15+Z15+AA15 -> 2.6190952 | AE15: =AC15-T15 -> 1.2523333 | AF15: =AC15-L15 -> -0.0078115942
B16: CED18663 | C16: SHENZHEN YUESHI SUPPLY | D16: SHEEP | E16: (blank) | F16: 25000 | G16: 9.8550725 | H16: 242857.14 | I16: 6 WAY | J16: CIF | K16: =IF(J16="CIF",G16-0.3,G16) -> 9.5550725 | L16: 8.4 | M16: =_xlfn.IFNA(VLOOKUP(I16,Sheet1!D:E,2,FALSE),0) -> 4 | N16: =_xlfn.IFNA(VLOOKUP(D16,Sheet1!G:H,2,FALSE),0) -> 8 | O16: =_xlfn.IFNA(VLOOKUP(D16,Sheet1!K:L,2,FALSE),0) -> 10 | P16: 27 | Q16: =IF(P16>0,(K16-L16)*P16+N16+O16-M16,0) -> 45.186957 | R16: =(93840/0.6963)/2 -> 67384.748 | T16: =IF(P16>0,(K16)-((40+M16-O16-N16)/P16),0) -> 8.5921095 | U16: =IF(P16>0,(F16/P16),0) -> 925.92593 | V16: =(L16*F16) -> 210000 | X16: =$G16-$X$5 -> 9.5550725 | Y16: =$M16/VLOOKUP($D16,$X$1:$Y$4,2,0) -> 0.18181818 | Z16: =$N16/VLOOKUP($D16,$X$1:$Y$4,2,0) -> 0.36363636 | AA16: =$O16/VLOOKUP($D16,$X$1:$Y$4,2,0) -> 0.45454545 | AB16: =X16-L16-Y16+Z16+AA16 -> 1.7914361 | AC16: =$X16*VLOOKUP($D16,$X$1:$AC$4,6,0) -> 7.9307101 | AD16: =X16-AC16-Y16+Z16+AA16 -> 2.260726 | AE16: =AC16-T16 -> -0.66139936 | AF16: =AC16-L16 -> -0.46928986
B17: CED18664 | C17: SHENZHEN YUESHI SUPPLY | D17: SHEEP | E17: (blank) | F17: 25000 | G17: 9.8550725 | H17: 242857.14 | I17: 6 WAY | J17: CIF | K17: =IF(J17="CIF",G17-0.3,G17) -> 9.5550725 | L17: 8.4 | M17: =_xlfn.IFNA(VLOOKUP(I17,Sheet1!D:E,2,FALSE),0) -> 4 | N17: =_xlfn.IFNA(VLOOKUP(D17,Sheet1!G:H,2,FALSE),0) -> 8 | O17: =_xlfn.IFNA(VLOOKUP(D17,Sheet1!K:L,2,FALSE),0) -> 10 | P17: 27 | Q17: =IF(P17>0,(K17-L17)*P17+N17+O17-M17,0) -> 45.186957 | R17: =(93840/0.6963)/2 -> 67384.748 | T17: =IF(P17>0,(K17)-((40+M17-O17-N17)/P17),0) -> 8.5921095 | U17: =IF(P17>0,(F17/P17),0) -> 925.92593 | V17: =(L17*F17) -> 210000 | X17: =$G17-$X$5 -> 9.5550725 | Y17: =$M17/VLOOKUP($D17,$X$1:$Y$4,2,0) -> 0.18181818 | Z17: =$N17/VLOOKUP($D17,$X$1:$Y$4,2,0) -> 0.36363636 | AA17: =$O17/VLOOKUP($D17,$X$1:$Y$4,2,0) -> 0.45454545 | AB17: =X17-L17-Y17+Z17+AA17 -> 1.7914361 | AC17: =$X17*VLOOKUP($D17,$X$1:$AC$4,6,0) -> 7.9307101 | AD17: =X17-AC17-Y17+Z17+AA17 -> 2.260726 | AE17: =AC17-T17 -> -0.66139936 | AF17: =AC17-L17 -> -0.46928986
B18: CEDD7045 | C18: AGRICOMM | D18: VEAL | E18: (blank) | F18: 25000 | G18: 6.85 | H18: 171250 | I18: 6 WAY | J18: FAS | K18: =IF(J18="CIF",G18-0.3,G18) -> 6.85 | L18: 3.2 | M18: =_xlfn.IFNA(VLOOKUP(I18,Sheet1!D:E,2,FALSE),0) -> 4 | N18: =_xlfn.IFNA(VLOOKUP(D18,Sheet1!G:H,2,FALSE),0) -> 11 | O18: =_xlfn.IFNA(VLOOKUP(D18,Sheet1!K:L,2,FALSE),0) -> 12 | P18: 17 | Q18: =IF(P18>0,(K18-L18)*P18+N18+O18-M18,0) -> 81.05 | R18: 166300.88 | T18: =IF(P18>0,(K18)-((40+M18-O18-N18)/P18),0) -> 5.6147059 | U18: =IF(P18>0,(F18/P18),0) -> 1470.5882 | V18: =(L18*F18) -> 80000 | X18: =$G18-$X$5 -> 6.55 | Y18: =$M18/VLOOKUP($D18,$X$1:$Y$4,2,0) -> 0.23529412 | Z18: =$N18/VLOOKUP($D18,$X$1:$Y$4,2,0) -> 0.64705882 | AA18: =$O18/VLOOKUP($D18,$X$1:$Y$4,2,0) -> 0.70588235 | AB18: =X18-L18-Y18+Z18+AA18 -> 4.4676471 | AC18: =$X18*VLOOKUP($D18,$X$1:$AC$4,6,0) -> 3.275 | AD18: =X18-AC18-Y18+Z18+AA18 -> 4.3926471 | AE18: =AC18-T18 -> -2.3397059 | AF18: =AC18-L18 -> 0.075
B19: CEDD7047 | C19: AGRICOMM | D19: VEAL | E19: (blank) | F19: 25000 | G19: 6.85 | H19: 171250 | I19: 6 WAY | J19: FAS | K19: =IF(J19="CIF",G19-0.3,G19) -> 6.85 | L19: 3.2 | M19: =_xlfn.IFNA(VLOOKUP(I19,Sheet1!D:E,2,FALSE),0) -> 4 | N19: =_xlfn.IFNA(VLOOKUP(D19,Sheet1!G:H,2,FALSE),0) -> 11 | O19: =_xlfn.IFNA(VLOOKUP(D19,Sheet1!K:L,2,FALSE),0) -> 12 | P19: 17 | Q19: =IF(P19>0,(K19-L19)*P19+N19+O19-M19,0) -> 81.05 | T19: =IF(P19>0,(K19)-((40+M19-O19-N19)/P19),0) -> 5.6147059 | U19: =IF(P19>0,(F19/P19),0) -> 1470.5882 | V19: =(L19*F19) -> 80000 | X19: =$G19-$X$5 -> 6.55 | Y19: =$M19/VLOOKUP($D19,$X$1:$Y$4,2,0) -> 0.23529412 | Z19: =$N19/VLOOKUP($D19,$X$1:$Y$4,2,0) -> 0.64705882 | AA19: =$O19/VLOOKUP($D19,$X$1:$Y$4,2,0) -> 0.70588235 | AB19: =X19-L19-Y19+Z19+AA19 -> 4.4676471 | AC19: =$X19*VLOOKUP($D19,$X$1:$AC$4,6,0) -> 3.275 | AD19: =X19-AC19-Y19+Z19+AA19 -> 4.3926471 | AE19: =AC19-T19 -> -2.3397059 | AF19: =AC19-L19 -> 0.075
B20: CEDD7048 | C20: AGRICOMM | D20: VEAL | E20: (blank) | F20: 25000 | G20: 6.85 | H20: 171250 | I20: 6 WAY | J20: FAS | K20: =IF(J20="CIF",G20-0.3,G20) -> 6.85 | L20: 3.2 | M20: =_xlfn.IFNA(VLOOKUP(I20,Sheet1!D:E,2,FALSE),0) -> 4 | N20: =_xlfn.IFNA(VLOOKUP(D20,Sheet1!G:H,2,FALSE),0) -> 11 | O20: =_xlfn.IFNA(VLOOKUP(D20,Sheet1!K:L,2,FALSE),0) -> 12 | P20: 17 | Q20: =IF(P20>0,(K20-L20)*P20+N20+O20-M20,0) -> 81.05 | T20: =IF(P20>0,(K20)-((40+M20-O20-N20)/P20),0) -> 5.6147059 | U20: =IF(P20>0,(F20/P20),0) -> 1470.5882 | V20: =(L20*F20) -> 80000 | X20: =$G20-$X$5 -> 6.55 | Y20: =$M20/VLOOKUP($D20,$X$1:$Y$4,2,0) -> 0.23529412 | Z20: =$N20/VLOOKUP($D20,$X$1:$Y$4,2,0) -> 0.64705882 | AA20: =$O20/VLOOKUP($D20,$X$1:$Y$4,2,0) -> 0.70588235 | AB20: =X20-L20-Y20+Z20+AA20 -> 4.4676471 | AC20: =$X20*VLOOKUP($D20,$X$1:$AC$4,6,0) -> 3.275 | AD20: =X20-AC20-Y20+Z20+AA20 -> 4.3926471 | AE20: =AC20-T20 -> -2.3397059 | AF20: =AC20-L20 -> 0.075
B21: CEDD7049 | C21: AGRICOMM | D21: VEAL | E21: (blank) | F21: 25000 | G21: 6.85 | H21: 171250 | I21: 6 WAY | J21: FAS | K21: =IF(J21="CIF",G21-0.3,G21) -> 6.85 | L21: 3.2 | M21: =_xlfn.IFNA(VLOOKUP(I21,Sheet1!D:E,2,FALSE),0) -> 4 | N21: =_xlfn.IFNA(VLOOKUP(D21,Sheet1!G:H,2,FALSE),0) -> 11 | O21: =_xlfn.IFNA(VLOOKUP(D21,Sheet1!K:L,2,FALSE),0) -> 12 | P21: 17 | Q21: =IF(P21>0,(K21-L21)*P21+N21+O21-M21,0) -> 81.05 | T21: =IF(P21>0,(K21)-((40+M21-O21-N21)/P21),0) -> 5.6147059 | U21: =IF(P21>0,(F21/P21),0) -> 1470.5882 | V21: =(L21*F21) -> 80000 | X21: =$G21-$X$5 -> 6.55 | Y21: =$M21/VLOOKUP($D21,$X$1:$Y$4,2,0) -> 0.23529412 | Z21: =$N21/VLOOKUP($D21,$X$1:$Y$4,2,0) -> 0.64705882 | AA21: =$O21/VLOOKUP($D21,$X$1:$Y$4,2,0) -> 0.70588235 | AB21: =X21-L21-Y21+Z21+AA21 -> 4.4676471 | AC21: =$X21*VLOOKUP($D21,$X$1:$AC$4,6,0) -> 3.275 | AD21: =X21-AC21-Y21+Z21+AA21 -> 4.3926471 | AE21: =AC21-T21 -> -2.3397059 | AF21: =AC21-L21 -> 0.075
B22: CEDD7050 | C22: AGRICOMM | D22: VEAL | E22: (blank) | F22: 25000 | G22: 6.85 | H22: 171250 | I22: 6 WAY | J22: FAS | K22: =IF(J22="CIF",G22-0.3,G22) -> 6.85 | L22: 3.2 | M22: =_xlfn.IFNA(VLOOKUP(I22,Sheet1!D:E,2,FALSE),0) -> 4 | N22: =_xlfn.IFNA(VLOOKUP(D22,Sheet1!G:H,2,FALSE),0) -> 11 | O22: =_xlfn.IFNA(VLOOKUP(D22,Sheet1!K:L,2,FALSE),0) -> 12 | P22: 17 | Q22: =IF(P22>0,(K22-L22)*P22+N22+O22-M22,0) -> 81.05 | T22: =IF(P22>0,(K22)-((40+M22-O22-N22)/P22),0) -> 5.6147059 | U22: =IF(P22>0,(F22/P22),0) -> 1470.5882 | V22: =(L22*F22) -> 80000 | X22: =$G22-$X$5 -> 6.55 | Y22: =$M22/VLOOKUP($D22,$X$1:$Y$4,2,0) -> 0.23529412 | Z22: =$N22/VLOOKUP($D22,$X$1:$Y$4,2,0) -> 0.64705882 | AA22: =$O22/VLOOKUP($D22,$X$1:$Y$4,2,0) -> 0.70588235 | AB22: =X22-L22-Y22+Z22+AA22 -> 4.4676471 | AC22: =$X22*VLOOKUP($D22,$X$1:$AC$4,6,0) -> 3.275 | AD22: =X22-AC22-Y22+Z22+AA22 -> 4.3926471 | AE22: =AC22-T22 -> -2.3397059 | AF22: =AC22-L22 -> 0.075
B23: CEDD7057 | C23: STELLA FOODS | D23: GOAT | E23: (blank) | F23: 24999 | G23: 9.5 | H23: 237490.5 | I23: 6 WAY | J23: FAS | K23: =IF(J23="CIF",G23-0.3,G23) -> 9.5 | L23: 7.7 | M23: =_xlfn.IFNA(VLOOKUP(I23,Sheet1!D:E,2,FALSE),0) -> 4 | N23: =_xlfn.IFNA(VLOOKUP(D23,Sheet1!G:H,2,FALSE),0) -> 6 | O23: 0.5 | P23: 14 | Q23: =IF(P23>0,(K23-L23)*P23+N23+O23-M23,0) -> 27.7 | T23: =IF(P23>0,(K23)-((40+M23-O23-N23)/P23),0) -> 6.8214286 | U23: =IF(P23>0,(F23/P23),0) -> 1785.6429 | V23: =(L23*F23) -> 192492.3 | X23: =$G23-$X$5 -> 9.2 | Y23: =$M23/VLOOKUP($D23,$X$1:$Y$4,2,0) -> 0.28571429 | Z23: =$N23/VLOOKUP($D23,$X$1:$Y$4,2,0) -> 0.42857143 | AA23: =$O23/VLOOKUP($D23,$X$1:$Y$4,2,0) -> 0.035714286 | AB23: =X23-L23-Y23+Z23+AA23 -> 1.6785714 | AC23: =$X23*VLOOKUP($D23,$X$1:$AC$4,6,0) -> 7.084 | AD23: =X23-AC23-Y23+Z23+AA23 -> 2.2945714 | AE23: =AC23-T23 -> 0.26257143 | AF23: =AC23-L23 -> -0.616
B24: CEDD7062 | C24: STELLA FOODS | D24: LAMB | E24: (blank) | F24: 17000 | G24: 11.6 | H24: 197200 | I24: CCS | J24: FAS | K24: =IF(J24="CIF",G24-0.3,G24) -> 11.6 | L24: 10.5 | M24: =_xlfn.IFNA(VLOOKUP(I24,Sheet1!D:E,2,FALSE),0) -> 2 | N24: =_xlfn.IFNA(VLOOKUP(D24,Sheet1!G:H,2,FALSE),0) -> 11 | O24: =_xlfn.IFNA(VLOOKUP(D24,Sheet1!K:L,2,FALSE),0) -> 10 | P24: 18 | Q24: =IF(P24>0,(K24-L24)*P24+N24+O24-M24,0) -> 38.8 | T24: =IF(P24>0,(K24)-((40+M24-O24-N24)/P24),0) -> 10.433333 | U24: =IF(P24>0,(F24/P24),0) -> 944.44444 | V24: =(L24*F24) -> 178500 | X24: =$G24-$X$5 -> 11.3 | Y24: =$M24/VLOOKUP($D24,$X$1:$Y$4,2,0) -> 0.11111111 | Z24: =$N24/VLOOKUP($D24,$X$1:$Y$4,2,0) -> 0.61111111 | AA24: =$O24/VLOOKUP($D24,$X$1:$Y$4,2,0) -> 0.55555556 | AB24: =X24-L24-Y24+Z24+AA24 -> 1.8555556 | AC24: =$X24*VLOOKUP($D24,$X$1:$AC$4,6,0) -> 9.379 | AD24: =X24-AC24-Y24+Z24+AA24 -> 2.9765556 | AE24: =AC24-T24 -> -1.0543333 | AF24: =AC24-L24 -> -1.121
B25: CEDD7063 | C25: STELLA FOODS | D25: LAMB | E25: (blank) | F25: 17000 | G25: 11.6 | H25: 197200 | I25: CCS | J25: FAS | K25: =IF(J25="CIF",G25-0.3,G25) -> 11.6 | L25: 10.5 | M25: =_xlfn.IFNA(VLOOKUP(I25,Sheet1!D:E,2,FALSE),0) -> 2 | N25: =_xlfn.IFNA(VLOOKUP(D25,Sheet1!G:H,2,FALSE),0) -> 11 | O25: =_xlfn.IFNA(VLOOKUP(D25,Sheet1!K:L,2,FALSE),0) -> 10 | P25: 18 | Q25: =IF(P25>0,(K25-L25)*P25+N25+O25-M25,0) -> 38.8 | T25: =IF(P25>0,(K25)-((40+M25-O25-N25)/P25),0) -> 10.433333 | U25: =IF(P25>0,(F25/P25),0) -> 944.44444 | V25: =(L25*F25) -> 178500 | X25: =$G25-$X$5 -> 11.3 | Y25: =$M25/VLOOKUP($D25,$X$1:$Y$4,2,0) -> 0.11111111 | Z25: =$N25/VLOOKUP($D25,$X$1:$Y$4,2,0) -> 0.61111111 | AA25: =$O25/VLOOKUP($D25,$X$1:$Y$4,2,0) -> 0.55555556 | AB25: =X25-L25-Y25+Z25+AA25 -> 1.8555556 | AC25: =$X25*VLOOKUP($D25,$X$1:$AC$4,6,0) -> 9.379 | AD25: =X25-AC25-Y25+Z25+AA25 -> 2.9765556 | AE25: =AC25-T25 -> -1.0543333 | AF25: =AC25-L25 -> -1.121
B26: CEDD7065 | C26: AGRICOMM | D26: GOAT | E26: (blank) | F26: 25000 | G26: 9.8 | H26: 245000 | I26: 6 WAY | J26: FAS | K26: =IF(J26="CIF",G26-0.3,G26) -> 9.8 | L26: 7.7 | M26: =_xlfn.IFNA(VLOOKUP(I26,Sheet1!D:E,2,FALSE),0) -> 4 | N26: =_xlfn.IFNA(VLOOKUP(D26,Sheet1!G:H,2,FALSE),0) -> 6 | O26: 0.5 | P26: 14 | Q26: =IF(P26>0,(K26-L26)*P26+N26+O26-M26,0) -> 31.9 | T26: =IF(P26>0,(K26)-((40+M26-O26-N26)/P26),0) -> 7.1214286 | U26: =IF(P26>0,(F26/P26),0) -> 1785.7143 | V26: =(L26*F26) -> 192500 | X26: =$G26-$X$5 -> 9.5 | Y26: =$M26/VLOOKUP($D26,$X$1:$Y$4,2,0) -> 0.28571429 | Z26: =$N26/VLOOKUP($D26,$X$1:$Y$4,2,0) -> 0.42857143 | AA26: =$O26/VLOOKUP($D26,$X$1:$Y$4,2,0) -> 0.035714286 | AB26: =X26-L26-Y26+Z26+AA26 -> 1.9785714 | AC26: =$X26*VLOOKUP($D26,$X$1:$AC$4,6,0) -> 7.315 | AD26: =X26-AC26-Y26+Z26+AA26 -> 2.3635714 | AE26: =AC26-T26 -> 0.19357143 | AF26: =AC26-L26 -> -0.385
B27: CEDD7069 | C27: GLOBAL MEAT COMMODITIES | D27: GOAT | E27: (blank) | F27: 24000 | G27: 9.65 | H27: 231600 | I27: 6 WAY | J27: FAS | K27: =IF(J27="CIF",G27-0.3,G27) -> 9.65 | L27: 7.7 | M27: =_xlfn.IFNA(VLOOKUP(I27,Sheet1!D:E,2,FALSE),0) -> 4 | N27: =_xlfn.IFNA(VLOOKUP(D27,Sheet1!G:H,2,FALSE),0) -> 6 | O27: 0.5 | P27: 14 | Q27: =IF(P27>0,(K27-L27)*P27+N27+O27-M27,0) -> 29.8 | T27: =IF(P27>0,(K27)-((40+M27-O27-N27)/P27),0) -> 6.9714286 | U27: =IF(P27>0,(F27/P27),0) -> 1714.2857 | V27: =(L27*F27) -> 184800 | X27: =$G27-$X$5 -> 9.35 | Y27: =$M27/VLOOKUP($D27,$X$1:$Y$4,2,0) -> 0.28571429 | Z27: =$N27/VLOOKUP($D27,$X$1:$Y$4,2,0) -> 0.42857143 | AA27: =$O27/VLOOKUP($D27,$X$1:$Y$4,2,0) -> 0.035714286 | AB27: =X27-L27-Y27+Z27+AA27 -> 1.8285714 | AC27: =$X27*VLOOKUP($D27,$X$1:$AC$4,6,0) -> 7.1995 | AD27: =X27-AC27-Y27+Z27+AA27 -> 2.3290714 | AE27: =AC27-T27 -> 0.22807143 | AF27: =AC27-L27 -> -0.5005
B28: CED18669 | C28: CHONGQING GOUZHAN INDUSTRIAL | D28: GOAT | E28: (blank) | F28: 16000 | G28: 10.072464 | H28: 158857.14 | I28: CCS | J28: CIF | K28: =IF(J28="CIF",G28-0.3,G28) -> 9.7724638 | L28: 7.7 | M28: =_xlfn.IFNA(VLOOKUP(I28,Sheet1!D:E,2,FALSE),0) -> 2 | N28: =_xlfn.IFNA(VLOOKUP(D28,Sheet1!G:H,2,FALSE),0) -> 6 | O28: 0.5 | P28: 10 | Q28: =IF(P28>0,(K28-L28)*P28+N28+O28-M28,0) -> 25.224638 | T28: =IF(P28>0,(K28)-((40+M28-O28-N28)/P28),0) -> 6.2224638 | U28: =IF(P28>0,(F28/P28),0) -> 1600 | V28: =(L28*F28) -> 123200 | X28: =$G28-$X$5 -> 9.7724638 | Y28: =$M28/VLOOKUP($D28,$X$1:$Y$4,2,0) -> 0.14285714 | Z28: =$N28/VLOOKUP($D28,$X$1:$Y$4,2,0) -> 0.42857143 | AA28: =$O28/VLOOKUP($D28,$X$1:$Y$4,2,0) -> 0.035714286 | AB28: =X28-L28-Y28+Z28+AA28 -> 2.3938923 | AC28: =$X28*VLOOKUP($D28,$X$1:$AC$4,6,0) -> 7.5247971 | AD28: =X28-AC28-Y28+Z28+AA28 -> 2.5690952 | AE28: =AC28-T28 -> 1.3023333 | AF28: =AC28-L28 -> -0.1752029
B29: CED18670 | C29: CHONGQING GOUZHAN INDUSTRIAL | D29: GOAT | E29: (blank) | F29: 16000 | G29: 10.144928 | H29: 160000 | I29: CCS | J29: CIF | K29: =IF(J29="CIF",G29-0.3,G29) -> 9.8449275 | L29: 7.7 | M29: =_xlfn.IFNA(VLOOKUP(I29,Sheet1!D:E,2,FALSE),0) -> 2 | N29: =_xlfn.IFNA(VLOOKUP(D29,Sheet1!G:H,2,FALSE),0) -> 6 | O29: 0.5 | P29: 10 | Q29: =IF(P29>0,(K29-L29)*P29+N29+O29-M29,0) -> 25.949275 | T29: =IF(P29>0,(K29)-((40+M29-O29-N29)/P29),0) -> 6.2949275 | U29: =IF(P29>0,(F29/P29),0) -> 1600 | V29: =(L29*F29) -> 123200 | X29: =$G29-$X$5 -> 9.8449275 | Y29: =$M29/VLOOKUP($D29,$X$1:$Y$4,2,0) -> 0.14285714 | Z29: =$N29/VLOOKUP($D29,$X$1:$Y$4,2,0) -> 0.42857143 | AA29: =$O29/VLOOKUP($D29,$X$1:$Y$4,2,0) -> 0.035714286 | AB29: =X29-L29-Y29+Z29+AA29 -> 2.4663561 | AC29: =$X29*VLOOKUP($D29,$X$1:$AC$4,6,0) -> 7.5805942 | AD29: =X29-AC29-Y29+Z29+AA29 -> 2.5857619 | AE29: =AC29-T29 -> 1.2856667 | AF29: =AC29-L29 -> -0.1194058
B30: CEDD7076 | C30: GLOBAL MEAT COMMODITIES | D30: GOAT | E30: (blank) | F30: 24000 | G30: 9.75 | H30: 234000 | I30: 6 WAY | J30: FAS | K30: =IF(J30="CIF",G30-0.3,G30) -> 9.75 | L30: 7.7 | M30: =_xlfn.IFNA(VLOOKUP(I30,Sheet1!D:E,2,FALSE),0) -> 4 | N30: =_xlfn.IFNA(VLOOKUP(D30,Sheet1!G:H,2,FALSE),0) -> 6 | O30: 0.5 | P30: 14 | Q30: =IF(P30>0,(K30-L30)*P30+N30+O30-M30,0) -> 31.2 | T30: =IF(P30>0,(K30)-((40+M30-O30-N30)/P30),0) -> 7.0714286 | U30: =IF(P30>0,(F30/P30),0) -> 1714.2857 | V30: =(L30*F30) -> 184800 | X30: =$G30-$X$5 -> 9.45 | Y30: =$M30/VLOOKUP($D30,$X$1:$Y$4,2,0) -> 0.28571429 | Z30: =$N30/VLOOKUP($D30,$X$1:$Y$4,2,0) -> 0.42857143 | AA30: =$O30/VLOOKUP($D30,$X$1:$Y$4,2,0) -> 0.035714286 | AB30: =X30-L30-Y30+Z30+AA30 -> 1.9285714 | AC30: =$X30*VLOOKUP($D30,$X$1:$AC$4,6,0) -> 7.2765 | AD30: =X30-AC30-Y30+Z30+AA30 -> 2.3520714 | AE30: =AC30-T30 -> 0.20507143 | AF30: =AC30-L30 -> -0.4235
B31: CEDD7085 | C31: BOUNTY FOODS | D31: LAMB | E31: (blank) | F31: 8100 | G31: 10.375 | H31: 83800 | I31: FULL BONE | J31: FAS | K31: =IF(J31="CIF",G31-0.3,G31) -> 10.375 | L31: 10.5 | M31: =_xlfn.IFNA(VLOOKUP(I31,Sheet1!D:E,2,FALSE),0) -> 7 | N31: =_xlfn.IFNA(VLOOKUP(D31,Sheet1!G:H,2,FALSE),0) -> 11 | O31: =_xlfn.IFNA(VLOOKUP(D31,Sheet1!K:L,2,FALSE),0) -> 10 | P31: 18 | Q31: =IF(P31>0,(K31-L31)*P31+N31+O31-M31,0) -> 11.75 | T31: =IF(P31>0,(K31)-((40+M31-O31-N31)/P31),0) -> 8.9305556 | U31: =IF(P31>0,(F31/P31),0) -> 450 | V31: =(L31*F31) -> 85050 | X31: =$G31-$X$5 -> 10.075 | Y31: =$M31/VLOOKUP($D31,$X$1:$Y$4,2,0) -> 0.38888889 | Z31: =$N31/VLOOKUP($D31,$X$1:$Y$4,2,0) -> 0.61111111 | AA31: =$O31/VLOOKUP($D31,$X$1:$Y$4,2,0) -> 0.55555556 | AB31: =X31-L31-Y31+Z31+AA31 -> 0.35277778 | AC31: =$X31*VLOOKUP($D31,$X$1:$AC$4,6,0) -> 8.36225 | AD31: =X31-AC31-Y31+Z31+AA31 -> 2.4905278 | AE31: =AC31-T31 -> -0.56830556 | AF31: =AC31-L31 -> -2.13775
B32: CEDD7089 | C32: GLOBAL MEAT COMMODITIES | D32: GOAT | E32: (blank) | F32: 25000 | G32: 10 | H32: 250000 | I32: 6 WAY | J32: FAS | K32: =IF(J32="CIF",G32-0.3,G32) -> 10 | L32: 7.7 | M32: =_xlfn.IFNA(VLOOKUP(I32,Sheet1!D:E,2,FALSE),0) -> 4 | N32: =_xlfn.IFNA(VLOOKUP(D32,Sheet1!G:H,2,FALSE),0) -> 6 | O32: 0.5 | P32: 14 | Q32: =IF(P32>0,(K32-L32)*P32+N32+O32-M32,0) -> 34.7 | T32: =IF(P32>0,(K32)-((40+M32-O32-N32)/P32),0) -> 7.3214286 | U32: =IF(P32>0,(F32/P32),0) -> 1785.7143 | V32: =(L32*F32) -> 192500 | X32: =$G32-$X$5 -> 9.7 | Y32: =$M32/VLOOKUP($D32,$X$1:$Y$4,2,0) -> 0.28571429 | Z32: =$N32/VLOOKUP($D32,$X$1:$Y$4,2,0) -> 0.42857143 | AA32: =$O32/VLOOKUP($D32,$X$1:$Y$4,2,0) -> 0.035714286 | AB32: =X32-L32-Y32+Z32+AA32 -> 2.1785714 | AC32: =$X32*VLOOKUP($D32,$X$1:$AC$4,6,0) -> 7.469 | AD32: =X32-AC32-Y32+Z32+AA32 -> 2.4095714 | AE32: =AC32-T32 -> 0.14757143 | AF32: =AC32-L32 -> -0.231
B33: CEDD7092 | C33: AGRICOMM | D33: VEAL | E33: (blank) | F33: 25000 | G33: 7.05 | H33: 176250 | I33: 6 WAY | J33: FAS | K33: =IF(J33="CIF",G33-0.3,G33) -> 7.05 | L33: 3.2 | M33: =_xlfn.IFNA(VLOOKUP(I33,Sheet1!D:E,2,FALSE),0) -> 4 | N33: =_xlfn.IFNA(VLOOKUP(D33,Sheet1!G:H,2,FALSE),0) -> 11 | O33: =_xlfn.IFNA(VLOOKUP(D33,Sheet1!K:L,2,FALSE),0) -> 12 | P33: 17 | Q33: =IF(P33>0,(K33-L33)*P33+N33+O33-M33,0) -> 84.45 | T33: =IF(P33>0,(K33)-((40+M33-O33-N33)/P33),0) -> 5.8147059 | U33: =IF(P33>0,(F33/P33),0) -> 1470.5882 | V33: =(L33*F33) -> 80000 | X33: =$G33-$X$5 -> 6.75 | Y33: =$M33/VLOOKUP($D33,$X$1:$Y$4,2,0) -> 0.23529412 | Z33: =$N33/VLOOKUP($D33,$X$1:$Y$4,2,0) -> 0.64705882 | AA33: =$O33/VLOOKUP($D33,$X$1:$Y$4,2,0) -> 0.70588235 | AB33: =X33-L33-Y33+Z33+AA33 -> 4.6676471 | AC33: =$X33*VLOOKUP($D33,$X$1:$AC$4,6,0) -> 3.375 | AD33: =X33-AC33-Y33+Z33+AA33 -> 4.4926471 | AE33: =AC33-T33 -> -2.4397059 | AF33: =AC33-L33 -> 0.175
B34: CEDD7093 | C34: AGRICOMM | D34: VEAL | E34: (blank) | F34: 25000 | G34: 7.05 | H34: 176250 | I34: 6 WAY | J34: FAS | K34: =IF(J34="CIF",G34-0.3,G34) -> 7.05 | L34: 3.2 | M34: =_xlfn.IFNA(VLOOKUP(I34,Sheet1!D:E,2,FALSE),0) -> 4 | N34: =_xlfn.IFNA(VLOOKUP(D34,Sheet1!G:H,2,FALSE),0) -> 11 | O34: =_xlfn.IFNA(VLOOKUP(D34,Sheet1!K:L,2,FALSE),0) -> 12 | P34: 17 | Q34: =IF(P34>0,(K34-L34)*P34+N34+O34-M34,0) -> 84.45 | T34: =IF(P34>0,(K34)-((40+M34-O34-N34)/P34),0) -> 5.8147059 | U34: =IF(P34>0,(F34/P34),0) -> 1470.5882 | V34: =(L34*F34) -> 80000 | X34: =$G34-$X$5 -> 6.75 | Y34: =$M34/VLOOKUP($D34,$X$1:$Y$4,2,0) -> 0.23529412 | Z34: =$N34/VLOOKUP($D34,$X$1:$Y$4,2,0) -> 0.64705882 | AA34: =$O34/VLOOKUP($D34,$X$1:$Y$4,2,0) -> 0.70588235 | AB34: =X34-L34-Y34+Z34+AA34 -> 4.6676471 | AC34: =$X34*VLOOKUP($D34,$X$1:$AC$4,6,0) -> 3.375 | AD34: =X34-AC34-Y34+Z34+AA34 -> 4.4926471 | AE34: =AC34-T34 -> -2.4397059 | AF34: =AC34-L34 -> 0.175
B35: Grand Total | F35: =SUM(F8:F34) -> 611096 | G35: =(H35/F35) -> 9.0985416 | H35: =SUM(H8:H34) -> 5560082.4 | R35: =SUM(R8:R34) -> 982321.43
B38: LOADED ORDERS
B39: Row Labels | C39: Customer Name | D39: Type | E39: Loadout Date | F39: Sum of Total QTY | G39: Average of Price AUD | H39: Sum of Amount AUD | I39: Product Type | J39: CIF or FAS ? | K39: NRV (per kg) | L39: Livestock Cost per kg (HSCW) | M39: Pack Cost | N39: Offal Return PH | O39: Avg Skin Return | P39: Avg Weight | Q39: MoM PH | S39: Comments | T39: Do Not Buy Price | U39: Estimated number of heads required | V39: Total Livestock Cost
B40: CED18649 | C40: TIANJIN NAVIGATOR INTERNATIONAL | D40: SHEEP | E40: 46205 | F40: 21617.16 | G40: 9.7101449 | H40: 206907.1 | I40: 6 WAY | J40: CIF | K40: =IF(J40="CIF",G40-0.3,G40) -> 9.4101449 | L40: 8.81 | M40: =_xlfn.IFNA(VLOOKUP(I40,Sheet1!D:E,2,FALSE),0) -> 4 | N40: =_xlfn.IFNA(VLOOKUP(D40,Sheet1!G:H,2,FALSE),0) -> 8 | O40: =_xlfn.IFNA(VLOOKUP(D40,Sheet1!K:L,2,FALSE),0) -> 10 | P40: 24.89 | Q40: =IF(P40>0,(K40-L40)*P40+N40+O40-M40,0) -> 28.937607 | T40: =IF(P40>0,(K40)-((34+M40-O40-N40)/P40),0) -> 8.6066094 | U40: =IF(P40>0,(F40/P40),0) -> 868.50783 | V40: =(L40*F40) -> 190447.18
B41: CED18654 | C41: DALIAN MAGIC INTERNATIONAL | D41: SHEEP | E41: 46212 | F41: 25004.6 | G41: 10.072464 | H41: 248259.96 | I41: 6 WAY | J41: CIF | K41: =IF(J41="CIF",G41-0.3,G41) -> 9.7724638 | L41: 8.21 | M41: =_xlfn.IFNA(VLOOKUP(I41,Sheet1!D:E,2,FALSE),0) -> 4 | N41: =_xlfn.IFNA(VLOOKUP(D41,Sheet1!G:H,2,FALSE),0) -> 8 | O41: =_xlfn.IFNA(VLOOKUP(D41,Sheet1!K:L,2,FALSE),0) -> 10 | P41: 18.24 | Q41: =IF(P41>0,(K41-L41)*P41+N41+O41-M41,0) -> 42.499339 | T41: =IF(P41>0,(K41)-((34+M41-O41-N41)/P41),0) -> 8.6759725 | U41: =IF(P41>0,(F41/P41),0) -> 1370.8662 | V41: =(L41*F41) -> 205287.77
B42: CED18656 | C42: JINAN WELCOME INDUSTRIAL | D42: MUTTON | E42: 46202 | F42: 15503.2 | G42: 9.7101449 | H42: 148387.77 | I42: CCS | J42: CIF | K42: =IF(J42="CIF",G42-0.3,G42) -> 9.4101449 | L42: 7.8 | M42: =_xlfn.IFNA(VLOOKUP(I42,Sheet1!D:E,2,FALSE),0) -> 2 | N42: =_xlfn.IFNA(VLOOKUP(D42,Sheet1!G:H,2,FALSE),0) -> 8 | O42: =_xlfn.IFNA(VLOOKUP(D42,Sheet1!K:L,2,FALSE),0) -> 10 | P42: 23.3 | Q42: =IF(P42>0,(K42-L42)*P42+N42+O42-M42,0) -> 53.516377 | T42: =IF(P42>0,(K42)-((34+M42-O42-N42)/P42),0) -> 8.6376127 | U42: =IF(P42>0,(F42/P42),0) -> 665.37339 | V42: =(L42*F42) -> 120924.96
B43: CEDD7044 | C43: AGRICOMM | D43: VEAL | E43: 46210 | F43: 25008.88 | G43: 6.85 | H43: 171310.83 | I43: 6 WAY | J43: FAS | K43: =IF(J43="CIF",G43-0.3,G43) -> 6.85 | L43: 3.11 | M43: =_xlfn.IFNA(VLOOKUP(I43,Sheet1!D:E,2,FALSE),0) -> 4 | N43: =_xlfn.IFNA(VLOOKUP(D43,Sheet1!G:H,2,FALSE),0) -> 11 | O43: =_xlfn.IFNA(VLOOKUP(D43,Sheet1!K:L,2,FALSE),0) -> 12 | P43: 18.8 | Q43: =IF(P43>0,(K43-L43)*P43+N43+O43-M43,0) -> 89.312 | T43: =IF(P43>0,(K43)-((34+M43-O43-N43)/P43),0) -> 6.0521277 | U43: =IF(P43>0,(F43/P43),0) -> 1330.2596 | V43: =(L43*F43) -> 77777.617
...

Sheet Summary
B2: Cashflow
H3: Weekly Working Capital
I4: 22 | J4: 9.67 | K4: 65000
C5: Avg Sell Price | D5: Avg LV Price | E5: Avg Weight | F5: Skin Return | G5: Heads | H5: Livestock | I5: Direct Labour | J5: VOH | K5: Salaries | L5: Total
B6: Lamb | C6: 11 | D6: 10 | E6: 18 | F6: 10 | G6: 1500 | H6: =(G6*D6*E6) -> 270000 | I6: =($I$4*G6) -> 33000 | J6: =($J$4*G6) -> 14505
B7: Mutton | C7: 9.75 | D7: 9 | E7: 20 | F7: 10 | G7: 1500 | H7: =(G7*D7*E7) -> 270000 | I7: =($I$4*G7) -> 33000 | J7: =($J$4*G7) -> 14505
B8: Goat | C8: 9.6 | D8: 7.9 | E8: 14 | F8: 0 | G8: 2000 | H8: =(G8*D8*E8) -> 221200 | I8: =($I$4*G8) -> 44000 | J8: =($J$4*G8) -> 19340
B9: Veal | C9: 6.85 | D9: 3.2 | E9: 17 | F9: 12.5 | G9: 2800 | H9: =(G9*D9*E9) -> 152320 | I9: =($I$4*G9) -> 61600 | J9: =($J$4*G9) -> 27076
G10: =SUM(G6:G9) -> 7800 | H10: =SUM(H6:H9) -> 913520 | I10: =SUM(I6:I9) -> 171600 | J10: =SUM(J6:J9) -> 75426 | K10: =(K4*1) -> 65000 | L10: =SUM(H10:K10) -> 1225546
E11: 10000
C12: Product | D12: Average Weight (kg) | E12: Number of heads for a 20 ft container
C13: Ovine Brains | D13: 0.12 | E13: =($E$11/D13) -> 83333.333
C14: Ovine Hearts | D14: 0.25 | E14: =($E$11/D14) -> 40000
C15: Ovine Kidneys (pair) | D15: 0.18 | E15: =($E$11/D15) -> 55555.556
C16: Ovine Livers | D16: 0.65 | E16: =($E$11/D16) -> 15384.615
C17: Ovine Lungs | D17: 0.6 | E17: =($E$11/D17) -> 16666.667
C18: Ovine Tongue | D18: 0.18 | E18: =($E$11/D18) -> 55555.556
C19: Ovine Sweetbreads | D19: 0.12 | E19: =($E$11/D19) -> 83333.333
C20: Lamb Runners | D20: 0.84 | E20: =($E$11/D20) -> 11904.762
C25: Assumptions
C26: Weeks to convert livestock to meat | E26: 1
C27: Weeks to convert meat to cash | E27: 2
C28: Weeks to convert skins to cash | E28: 3
C29: Weeks to convert offal to cash | E29: 5
C30: Number of working capital weeks required | E30: 5
C31: Working capital required | E31: =(L10*E30) -> 6127730
B35: Profitability
C37: Expected MOM PH | D37: Direct Labour PH | E37: VOH PH | F37: Gross Margin PH | G37: Gross Margin | H37: FOH Cost PW | I37: EBITDA PW
B38: Lamb | C38: 30 | D38: 19.25 | E38: 9.67 | F38: =(C38-D38-E38) -> 1.08 | G38: =(F38*G6) -> 1620 | H38: =(H42/$G$10)*G6 -> 38680.913 | I38: =(G38-H38) -> -37060.913
B39: Mutton | C39: 30 | D39: 19.25 | E39: 9.67 | F39: =(C39-D39-E39) -> 1.08 | G39: =(F39*G7) -> 1620 | H39: =(H42/$G$10)*G7 -> 38680.913 | I39: =(G39-H39) -> -37060.913
B40: Goat | C40: 30 | D40: 19.25 | E40: 9.67 | F40: =(C40-D40-E40) -> 1.08 | G40: =(F40*G8) -> 2160 | H40: =(H42/$G$10)*G8 -> 51574.551 | I40: =(G40-H40) -> -49414.551
B41: Veal | C41: 76.4 | D41: 19.25 | E41: 9.67 | F41: =(C41-D41-E41) -> 47.48 | G41: =(F41*G9) -> 132944 | H41: =(H42/$G$10)*G9 -> 72204.372 | I41: =(G41-H41) -> 60739.628
F42: =(G42/G10) -> 17.73641 | G42: =SUM(G38:G41) -> 138344 | H42: =(804563/4) -> 201140.75 | I42: =(G42-H42) -> -62796.75
B46: Incresing revenue
B48: Additional Offal collection
B50: Offal Type | C50: NRV
B51: Brains | C51: 1.64
B52: Hocks | C52: 2
C53: =(C51*G6) -> 2460
C54: =(C52)*(G6+G7) -> 6000
...

Sheet Offal
E1: 3000
B2: Product | C2: Average Weight (kg) | D2: Number of heads for a 20 ft container | E2: Weight of a load | F2: Wks for a load | G2: Revenue per head
B3: Ovine Brains | C3: 0.12 | D3: 83333.333 | E3: 800 | F3: =(E3/C3)/$E$1 -> 2.2222222 | H3: 1.65
B4: Ovine Hearts | C4: 0.25 | D4: 40000 | E4: 800 | F4: =(E4/C4)/$E$1 -> 1.0666667 | G4: 1.47
B5: Ovine Kidneys (pair) | C5: 0.18 | D5: 55555.556 | E5: 800 | F5: =(E5/C5)/$E$1 -> 1.4814815 | G5: 0.84
B6: Ovine Livers | C6: 0.65 | D6: 15384.615 | E6: 800 | F6: =(E6/C6)/$E$1 -> 0.41025641 | G6: 2.1
B7: Ovine Lungs | C7: 0.6 | D7: 16666.667 | E7: 800 | F7: =(E7/C7)/$E$1 -> 0.44444444 | G7: 1.62
B8: Ovine Tongue | C8: 0.18 | D8: 55555.556 | E8: 800 | F8: =(E8/C8)/$E$1 -> 1.4814815 | G8: 1.56
B9: Ovine Sweetbreads | C9: 0.12 | D9: 83333.333 | E9: 800 | F9: =(E9/C9)/$E$1 -> 2.2222222 | H9: 1.44
B10: Lamb Runners | C10: 0.84 | D10: 11904.762 | E10: 10000 | F10: =(E10/C10)/$E$1 -> 3.968254 | G10: 4.38
G11: =SUM(G3:G10) -> 11.97

Sheet Veal
A1: VEAL KILLED FROM 1ST JULY 2024 TO PRESENT
A2: Date | B2: No. of Heads Killed | G2: Week | H2: Heads | I2: Month
A3: 45474 | B3: 266 | C3: =WEEKNUM(A3,2) -> 27 | D3: =TEXT(A3,"mmm") -> Jul | G3: 27 | H3: =SUMIF(C:C,G3,B:B) -> 1414 | I3: =VLOOKUP(G3,C:D,2,FALSE) -> Jul
A4: 45475 | B4: 130 | C4: =WEEKNUM(A4,2) -> 27 | D4: =TEXT(A4,"mmm") -> Jul | G4: 28 | H4: =SUMIF(C:C,G4,B:B) -> 1791 | I4: =VLOOKUP(G4,C:D,2,FALSE) -> Jul
A5: 45476 | B5: 63 | C5: =WEEKNUM(A5,2) -> 27 | D5: =TEXT(A5,"mmm") -> Jul | G5: 29 | H5: =SUMIF(C:C,G5,B:B) -> 1384 | I5: =VLOOKUP(G5,C:D,2,FALSE) -> Jul
A6: 45477 | B6: 392 | C6: =WEEKNUM(A6,2) -> 27 | D6: =TEXT(A6,"mmm") -> Jul | G6: 30 | H6: =SUMIF(C:C,G6,B:B) -> 1819 | I6: =VLOOKUP(G6,C:D,2,FALSE) -> Jul
A7: 45478 | B7: 23 | C7: =WEEKNUM(A7,2) -> 27 | D7: =TEXT(A7,"mmm") -> Jul | G7: 31 | H7: =SUMIF(C:C,G7,B:B) -> 2256 | I7: =VLOOKUP(G7,C:D,2,FALSE) -> Jul
A8: 45481 | B8: 314 | C8: =WEEKNUM(A8,2) -> 28 | D8: =TEXT(A8,"mmm") -> Jul | G8: 32 | H8: =SUMIF(C:C,G8,B:B) -> 3248 | I8: =VLOOKUP(G8,C:D,2,FALSE) -> Aug
A9: 45482 | B9: 243 | C9: =WEEKNUM(A9,2) -> 28 | D9: =TEXT(A9,"mmm") -> Jul | G9: 33 | H9: =SUMIF(C:C,G9,B:B) -> 4761 | I9: =VLOOKUP(G9,C:D,2,FALSE) -> Aug
A10: 45483 | B10: 64 | C10: =WEEKNUM(A10,2) -> 28 | D10: =TEXT(A10,"mmm") -> Jul | G10: 34 | H10: =SUMIF(C:C,G10,B:B) -> 8106 | I10: =VLOOKUP(G10,C:D,2,FALSE) -> Aug
A11: 45484 | B11: 378 | C11: =WEEKNUM(A11,2) -> 28 | D11: =TEXT(A11,"mmm") -> Jul | G11: 35 | H11: =SUMIF(C:C,G11,B:B) -> 8315 | I11: =VLOOKUP(G11,C:D,2,FALSE) -> Aug
A12: 45485 | B12: 107 | C12: =WEEKNUM(A12,2) -> 28 | D12: =TEXT(A12,"mmm") -> Jul | G12: 36 | H12: =SUMIF(C:C,G12,B:B) -> 6858 | I12: =VLOOKUP(G12,C:D,2,FALSE) -> Sep
A13: 45488 | B13: 406 | C13: =WEEKNUM(A13,2) -> 29 | D13: =TEXT(A13,"mmm") -> Jul | G13: 37 | H13: =SUMIF(C:C,G13,B:B) -> 6561 | I13: =VLOOKUP(G13,C:D,2,FALSE) -> Sep
A14: 45489 | B14: 249 | C14: =WEEKNUM(A14,2) -> 29 | D14: =TEXT(A14,"mmm") -> Jul | G14: 38 | H14: =SUMIF(C:C,G14,B:B) -> 4893 | I14: =VLOOKUP(G14,C:D,2,FALSE) -> Sep
... A19: 45496 | B19: 274 | C19: =WEEKNUM(A19,2) -> 30 | D19: =TEXT(A19,"mmm") -> Jul | G19: 43 | H19: =SUMIF(C:C,G19,B:B) -> 1509 | I19: =VLOOKUP(G19,C:D,2,FALSE) -> Oct
A20: 45497 | B20: 216 | C20: =WEEKNUM(A20,2) -> 30 | D20: =TEXT(A20,"mmm") -> Jul
A21: 45498 | B21: 594 | C21: =WEEKNUM(A21,2) -> 30 | D21: =TEXT(A21,"mmm") -> Jul
A22: 45499 | B22: 347 | C22: =WEEKNUM(A22,2) -> 30 | D22: =TEXT(A22,"mmm") -> Jul
A23: 45502 | B23: 670 | C23: =WEEKNUM(A23,2) -> 31 | D23: =TEXT(A23,"mmm") -> Jul
A24: 45503 | B24: 368 | C24: =WEEKNUM(A24,2) -> 31 | D24: =TEXT(A24,"mmm") -> Jul
A25: 45504 | B25: 224 | C25: =WEEKNUM(A25,2) -> 31 | D25: =TEXT(A25,"mmm") -> Jul
A26: 45505 | B26: 601 | C26: =WEEKNUM(A26,2) -> 31 | D26: =TEXT(A26,"mmm") -> Aug
A27: 45506 | B27: 393 | C27: =WEEKNUM(A27,2) -> 31 | D27: =TEXT(A27,"mmm") -> Aug
A28: 45509 | B28: 1047 | C28: =WEEKNUM(A28,2) -> 32 | D28: =TEXT(A28,"mmm") -> Aug
A29: 45510 | B29: 473 | C29: =WEEKNUM(A29,2) -> 32 | D29: =TEXT(A29,"mmm") -> Aug
A30: 45511 | B30: 196 | C30: =WEEKNUM(A30,2) -> 32 | D30: =TEXT(A30,"mmm") -> Aug
A31: 45512 | B31: 983 | C31: =WEEKNUM(A31,2) -> 32 | D31: =TEXT(A31,"mmm") -> Aug
... A347: 46185 | B347: 79 | C347: =WEEKNUM(A347,2) -> 24 | D347: =TEXT(A347,"mmm") -> Jun

Sheet Financial Data
A2: Sales Representative | B2: Peter
A3: Status | B3: (Multiple Items)
A5: Row Labels | B5: Customer Name | C5: Type | D5: Loadout Date | E5: Sum of Total QTY | F5: Average of Price AUD | G5: Sum of Amount AUD | H5: CIF or FAS ? | I5: Ranking | J5: CIF | N5: profit Ranking | O5: Profit Band | P5: Estimated Margin at livestock level | Q5: Do not buy price | R5: Post production analysis
A6: CED18649 | B6: TIANJIN NAVIGATOR INTERNATIONAL | C6: SHEEP | D6: 46205 | E6: 23000 | F6: 9.7101449 | G6: 220142.86 | H6: CIF | I6: A | J6: =+F6-0.4 -> 9.3101449 | N6: 4 | O6: C
A7: CED18650 | B7: SHANGHAI NEW SOURCE | C7: SHEEP | D7: (blank) | E7: 25000 | F7: 10.144928 | G7: 250000 | H7: CIF | I7: A | J7: =+F7-0.4 -> 9.7449275 | N7: 3 | O7: B | P7: 3 | Q7: $3.50 FOR VEAL
A8: CED18651 | B8: SHANGHAI NEW SOURCE | C8: SHEEP | D8: (blank) | E8: 25000 | F8: 10.144928 | G8: 250000 | H8: CIF | I8: A | J8: =+F8-0.4 -> 9.7449275 | N8: 2 | O8: B | P8: 1.5 | Q8: $8.30 FOR GOATS
A9: CED18653 | B9: DALIAN MAGIC INTERNATIONAL | C9: SHEEP | D9: (blank) | E9: 22000 | F9: 9.7101449 | G9: 210571.43 | H9: CIF | I9: A | J9: =+F9-0.4 -> 9.3101449 | N9: 1 | O9: A | P9: 0.8 | Q9: $11.00 FOR LAMBS
A10: CED18654 | B10: DALIAN MAGIC INTERNATIONAL | C10: SHEEP | D10: (blank) | E10: 25000 | F10: 10.072464 | G10: 248214.29 | H10: CIF | I10: A | J10: =+F10-0.4 -> 9.6724638 | N10: 5 | O10: c | P10: 0.8 | Q10: $9.30 FOR MUTTON
A11: CED18655 | B11: DALIAN MAGIC INTERNATIONAL | C11: SHEEP | D11: (blank) | E11: 25000 | F11: 10.072464 | G11: 248214.29 | H11: CIF | I11: A | J11: =+F11-0.4 -> 9.6724638 | N11: 6 | O11: c
A12: CED18656 | B12: JINAN WELCOME INDUSTRIAL | C12: MUTTON | D12: 46202 | E12: 15503.2 | F12: 9.7101449 | G12: 148387.77 | H12: CIF | I12: C | J12: =+F12-0.4 -> 9.3101449 | N12: 7 | O12: c
A13: CED18658 | B13: CHONGQING GOUZHAN INDUSTRIAL | C13: GOAT | D13: (blank) | E13: 24999 | F13: 10 | G13: 246418.71 | H13: CIF | I13: A | J13: =+F13-0.4 -> 9.6 | N13: 13 | O13: c
A14: CED18659 | B14: CHONGQING GOUZHAN INDUSTRIAL | C14: GOAT | D14: (blank) | E14: 24999 | F14: 10 | G14: 246418.71 | H14: CIF | I14: A | J14: =+F14-0.4 -> 9.6 | N14: 9 | O14: c
A15: CED18660 | B15: SHENZHEN YUESHI SUPPLY | C15: GOAT | D15: (blank) | E15: 24999 | F15: 10 | G15: 246418.71 | H15: CIF | I15: A | J15: =+F15-0.4 -> 9.6
A16: CED18662 | B16: CHONGQING GOUZHAN INDUSTRIAL | C16: GOAT | D16: (blank) | E16: 17000 | F16: 10.289855 | G16: 172428.57 | H16: CIF | I16: A | J16: =+F16-0.4 -> 9.8898551
A17: CED18663 | B17: SHENZHEN YUESHI SUPPLY | C17: SHEEP | D17: (blank) | E17: 25000 | F17: 9.8550725 | G17: 242857.14 | H17: CIF | I17: A | J17: =+F17-0.4 -> 9.4550725
A18: CED18664 | B18: SHENZHEN YUESHI SUPPLY | C18: SHEEP | D18: (blank) | E18: 25000 | F18: 9.8550725 | G18: 242857.14 | H18: CIF | I18: A | J18: =+F18-0.4 -> 9.4550725
A19: CEDD6957 | B19: SURE GOOD FOODS | C19: GOAT | D19: (blank) | E19: 24999 | F19: 8.4 | G19: 209991.6 | H19: FAS | I19: C | J19: FAS
A20: CEDD7044 | B20: AGRICOMM | C20: VEAL | D20: (blank) | E20: 25000 | F20: 6.85 | G20: 171250 | H20: FAS | I20: A | J20: FAS
A21: CEDD7045 | B21: AGRICOMM | C21: VEAL | D21: (blank) | E21: 25000 | F21: 6.85 | G21: 171250 | H21: FAS | I21: A | J21: FAS
A22: CEDD7046 | B22: AGRICOMM | C22: VEAL | D22: (blank) | E22: 25000 | F22: 6.85 | G22: 171250 | H22: FAS | I22: A | J22: FAS | N22: Profit Ranking (Peter) | O22: All orders to be ranked from 1 to n , 1 being the most profitable
A23: CEDD7047 | B23: AGRICOMM | C23: VEAL | D23: (blank) | E23: 25000 | F23: 6.85 | G23: 171250 | H23: FAS | I23: A | J23: FAS | N23: Profit Band (Peter) | O23: Only 3 bands A , B , C . A being highly protable B just about profitable C loss making Please set the band metrics Please attached calculation
A24: CEDD7048 | B24: AGRICOMM | C24: VEAL | D24: (blank) | E24: 25000 | F24: 6.85 | G24: 171250 | H24: FAS | I24: A | J24: FAS | N24: Estimated Margin (Peter) | O24: This is sales achieved less livestock cost plus transport ie livestock at the plant exclude offals and skins (Calculation to be attached)
A25: CEDD7049 | B25: AGRICOMM | C25: VEAL | D25: (blank) | E25: 25000 | F25: 6.85 | G25: 171250 | H25: FAS | I25: A | J25: FAS | N25: Do NOT Buy price (Peter) | O25: Buyer cannot buy anything above this price. Buyer must attempt to achieve below ths do not buy price
A26: CEDD7050 | B26: AGRICOMM | C26: VEAL | D26: (blank) | E26: 25000 | F26: 6.85 | G26: 171250 | H26: FAS | I26: A | J26: FAS | N26: Post production analysis | O26: This calculate the actual margin at actual livestock price and actual transport cost exclude offals and skins This will be compared with Estimated Margin . Calculation to bde attached
A27: CEDD7057 | B27: STELLA FOODS | C27: GOAT | D27: (blank) | E27: 24999 | F27: 9.5 | G27: 237490.5 | H27: FAS | I27: B | J27: FAS | N27: Note | O27: All of this analysis exclude offals and skins but include transport cost
A28: CEDD7060 | B28: AGRICOMM | C28: LAMB | D28: 46206 | E28: 17000 | F28: 11.5 | G28: 195500 | H28: FAS | I28: B | J28: FAS
A29: CEDD7062 | B29: STELLA FOODS | C29: LAMB | D29: (blank) | E29: 17000 | F29: 11.6 | G29: 197200 | H29: FAS | I29: A | J29: FAS
A30: CEDD7063 | B30: STELLA FOODS | C30: LAMB | D30: (blank) | E30: 17000 | F30: 11.6 | G30: 197200 | H30: FAS | I30: A | J30: FAS
A31: CEDD7065 | B31: AGRICOMM | C31: GOAT | D31: (blank) | E31: 25000 | F31: 9.8 | G31: 245000 | H31: FAS | I31: A | J31: FAS
A32: CEDD7067 | B32: MIDFIELD COMMODITIES | C32: VEAL | D32: (blank) | E32: 25000 | F32: 6.65 | G32: 166250 | H32: FAS | I32: A | J32: FAS
A33: CEDD7068 | B33: MIDFIELD COMMODITIES | C33: VEAL | D33: (blank) | E33: 25000 | F33: 6.65 | G33: 166250 | H33: FAS | I33: A | J33: FAS
A34: CEDD7069 | B34: GLOBAL MEAT COMMODITIES | C34: GOAT | D34: (blank) | E34: 24000 | F34: 9.65 | G34: 231600 | H34: FAS | I34: B | J34: FAS
A35: CEDD7070 | B35: SWIFT & COMPANY | C35: LAMB | D35: 46206 | E35: 10000 | F35: 11 | G35: 110000 | H35: FAS | I35: A | J35: FAS
A36: CEDD7072 | B36: GLOBAL MEAT COMMODITIES | C36: GOAT | D36: (blank) | E36: 24000 | F36: 9.75 | G36: 234000 | H36: FAS | I36: A | J36: FAS
A37: CEDD7073 | B37: GLOBAL MEAT COMMODITIES | C37: GOAT | D37: (blank) | E37: 24000 | F37: 9.75 | G37: 234000 | H37: FAS | I37: A | J37: FAS
A38: CED18669 | B38: CHONGQING GOUZHAN INDUSTRIAL | C38: GOAT | D38: (blank) | E38: 16000 | F38: 10.072464 | G38: 158857.14 | H38: CIF | I38: A | J38: =+F38-0.4 -> 9.6724638
A39: CED18670 | B39: CHONGQING GOUZHAN INDUSTRIAL | C39: GOAT | D39: (blank) | E39: 16000 | F39: 10.144928 | G39: 160000 | H39: CIF | I39: A | J39: =+F39-0.4 -> 9.7449275
A40: CEDD7076 | B40: GLOBAL MEAT COMMODITIES | C40: GOAT | D40: (blank) | E40: 24000 | F40: 9.75 | G40: 234000 | H40: CIF | I40: A | J40: FAS
A41: Grand Total | E41: 791498.2 | F41: 8.5489942 | G41: 7149018.9

Sheet Sheet1
G2: Offal | K2: Skins
B3: CIF | D3: CCS | E3: 2 | G3: SHEEP | H3: 8 | K3: SHEEP | L3: 10 | O3: SHEEP | P3: 22
B4: FAS | D4: 6 Way | E4: 4 | G4: MUTTON | H4: 8 | K4: MUTTON | L4: 10 | O4: MUTTON | P4: 24
D5: Full Bone | E5: 7 | G5: GOAT | H5: 6 | K5: GOAT | L5: 0 | O5: GOAT | P5: 14
G6: VEAL | H6: 11 | K6: VEAL | L6: 12 | O6: VEAL | P6: 17
G7: LAMB | H7: 11 | K7: LAMB | L7: 10 | O7: LAMB | P7: 19
B11: A being highly protable B just about profitable C loss making
